Workbook

Sheet INTERESES
A1: FECHA | B1: PUESTO | C1: NOMBRE | D1: RECIBO | E1: MONTO | F1: DETALLE

Sheet MATRIZ
A3: PAGOS DEL ALQUILER
B4: COSTO | C4: PAGO 1 | D4: PAGO 2 | E4: PAGO 3 | F4: PAGO 4 | G4: PAGO 5 | H4: PAGO 6 | I4: PAGO 7 | J4: PAGO 8 | K4: SALDO | L4: RECAUDADO
A5: Enero | K5: =MATRIZ!$B5-(MATRIZ!$C5+MATRIZ!$D5+MATRIZ!$E5+MATRIZ!$F5+MATRIZ!$G5+MATRIZ!$H5+MATRIZ!$I5+MATRIZ!$J5) -> 0 | L5: =MATRIZ!$B5-MATRIZ!$K5 -> 0
A6: Febrero | K6: =MATRIZ!$B6-(MATRIZ!$C6+MATRIZ!$D6+MATRIZ!$E6+MATRIZ!$F6+MATRIZ!$G6+MATRIZ!$H6+MATRIZ!$I6+MATRIZ!$J6) -> 0 | L6: =MATRIZ!$B6-MATRIZ!$K6 -> 0
A7: Marzo | K7: =MATRIZ!$B7-(MATRIZ!$C7+MATRIZ!$D7+MATRIZ!$E7+MATRIZ!$F7+MATRIZ!$G7+MATRIZ!$H7+MATRIZ!$I7+MATRIZ!$J7) -> 0 | L7: =MATRIZ!$B7-MATRIZ!$K7 -> 0
A8: Abril | K8: =MATRIZ!$B8-(MATRIZ!$C8+MATRIZ!$D8+MATRIZ!$E8+MATRIZ!$F8+MATRIZ!$G8+MATRIZ!$H8+MATRIZ!$I8+MATRIZ!$J8) -> 0 | L8: =MATRIZ!$B8-MATRIZ!$K8 -> 0
A9: Mayo | K9: =MATRIZ!$B9-(MATRIZ!$C9+MATRIZ!$D9+MATRIZ!$E9+MATRIZ!$F9+MATRIZ!$G9+MATRIZ!$H9+MATRIZ!$I9+MATRIZ!$J9) -> 0 | L9: =MATRIZ!$B9-MATRIZ!$K9 -> 0
A10: Junio | K10: =MATRIZ!$B10-(MATRIZ!$C10+MATRIZ!$D10+MATRIZ!$E10+MATRIZ!$F10+MATRIZ!$G10+MATRIZ!$H10+MATRIZ!$I10+MATRIZ!$J10) -> 0 | L10: =MATRIZ!$B10-MATRIZ!$K10 -> 0
A11: Julio | K11: =MATRIZ!$B11-(MATRIZ!$C11+MATRIZ!$D11+MATRIZ!$E11+MATRIZ!$F11+MATRIZ!$G11+MATRIZ!$H11+MATRIZ!$I11+MATRIZ!$J11) -> 0 | L11: =MATRIZ!$B11-MATRIZ!$K11 -> 0
A12: Agosto | K12: =MATRIZ!$B12-(MATRIZ!$C12+MATRIZ!$D12+MATRIZ!$E12+MATRIZ!$F12+MATRIZ!$G12+MATRIZ!$H12+MATRIZ!$I12+MATRIZ!$J12) -> 0 | L12: =MATRIZ!$B12-MATRIZ!$K12 -> 0
A13: Septiembre | K13: =MATRIZ!$B13-(MATRIZ!$C13+MATRIZ!$D13+MATRIZ!$E13+MATRIZ!$F13+MATRIZ!$G13+MATRIZ!$H13+MATRIZ!$I13+MATRIZ!$J13) -> 0 | L13: =MATRIZ!$B13-MATRIZ!$K13 -> 0
A14: Octubre | K14: =MATRIZ!$B14-(MATRIZ!$C14+MATRIZ!$D14+MATRIZ!$E14+MATRIZ!$F14+MATRIZ!$G14+MATRIZ!$H14+MATRIZ!$I14+MATRIZ!$J14) -> 0 | L14: =MATRIZ!$B14-MATRIZ!$K14 -> 0
A15: Noviembre | K15: =MATRIZ!$B15-(MATRIZ!$C15+MATRIZ!$D15+MATRIZ!$E15+MATRIZ!$F15+MATRIZ!$G15+MATRIZ!$H15+MATRIZ!$I15+MATRIZ!$J15) -> 0 | L15: =MATRIZ!$B15-MATRIZ!$K15 -> 0
A16: Diciembre | K16: =MATRIZ!$B16-(MATRIZ!$C16+MATRIZ!$D16+MATRIZ!$E16+MATRIZ!$F16+MATRIZ!$G16+MATRIZ!$H16+MATRIZ!$I16+MATRIZ!$J16) -> 0 | L16: =MATRIZ!$B16-MATRIZ!$K16 -> 0
A18: NRO DE RECIBOS DE LOS PAGOS
C19: RECIBO 1 | D19: RECIBO 2 | E19: RECIBO 3 | F19: RECIBO 4 | G19: RECIBO 5 | H19: RECIBO 6 | I19: RECIBO 7 | J19: RECIBO 8
A20: Enero
A21: Febrero
A22: Marzo
A23: Abril
A24: Mayo
A25: Junio
A26: Julio
A27: Agosto
A28: Septiembre
A29: Octubre
A30: Noviembre
A31: Diciembre

Sheet P001
A1: Pto.1/2/3/21/22/23/loc23 | C1: HERNAN NIELSEN
A3: PAGOS DEL ALQUILER
B4: 1183800 | C4: PAGO 1 | D4: PAGO 2 | E4: PAGO 3 | F4: PAGO 4 | G4: PAGO 5 | H4: PAGO 6 | I4: PAGO 7 | J4: PAGO 8 | K4: SALDO | L4: RECAUDADO
A5: Enero | B5: 1183800 | C5: 1183800 | K5: ='P001'!$B5-('P001'!$C5+'P001'!$D5+'P001'!$E5+'P001'!$F5+'P001'!$G5+'P001'!$H5+'P001'!$I5+'P001'!$J5) -> 0 | L5: ='P001'!$B5-'P001'!$K5 -> 1183800 | M5: 54000
A6: Febrero | B6: 1183800 | C6: 1183800 | K6: ='P001'!$B6-('P001'!$C6+'P001'!$D6+'P001'!$E6+'P001'!$F6+'P001'!$G6+'P001'!$H6+'P001'!$I6+'P001'!$J6) -> 0 | L6: ='P001'!$B6-'P001'!$K6 -> 1183800 | M6: 54000
A7: Marzo | B7: 1287900 | C7: 1287900 | K7: ='P001'!$B7-('P001'!$C7+'P001'!$D7+'P001'!$E7+'P001'!$F7+'P001'!$G7+'P001'!$H7+'P001'!$I7+'P001'!$J7) -> 0 | L7: ='P001'!$B7-'P001'!$K7 -> 1287900 | M7: 54000
A8: Abril | K8: ='P001'!$B8-('P001'!$C8+'P001'!$D8+'P001'!$E8+'P001'!$F8+'P001'!$G8+'P001'!$H8+'P001'!$I8+'P001'!$J8) -> 0 | L8: ='P001'!$B8-'P001'!$K8 -> 0
A9: Mayo | K9: ='P001'!$B9-('P001'!$C9+'P001'!$D9+'P001'!$E9+'P001'!$F9+'P001'!$G9+'P001'!$H9+'P001'!$I9+'P001'!$J9) -> 0 | L9: ='P001'!$B9-'P001'!$K9 -> 0
A10: Junio | K10: ='P001'!$B10-('P001'!$C10+'P001'!$D10+'P001'!$E10+'P001'!$F10+'P001'!$G10+'P001'!$H10+'P001'!$I10+'P001'!$J10) -> 0 | L10: ='P001'!$B10-'P001'!$K10 -> 0
A11: Julio | K11: ='P001'!$B11-('P001'!$C11+'P001'!$D11+'P001'!$E11+'P001'!$F11+'P001'!$G11+'P001'!$H11+'P001'!$I11+'P001'!$J11) -> 0 | L11: ='P001'!$B11-'P001'!$K11 -> 0
A12: Agosto | K12: ='P001'!$B12-('P001'!$C12+'P001'!$D12+'P001'!$E12+'P001'!$F12+'P001'!$G12+'P001'!$H12+'P001'!$I12+'P001'!$J12) -> 0 | L12: ='P001'!$B12-'P001'!$K12 -> 0
A13: Septiembre | K13: ='P001'!$B13-('P001'!$C13+'P001'!$D13+'P001'!$E13+'P001'!$F13+'P001'!$G13+'P001'!$H13+'P001'!$I13+'P001'!$J13) -> 0 | L13: ='P001'!$B13-'P001'!$K13 -> 0
A14: Octubre | K14: ='P001'!$B14-('P001'!$C14+'P001'!$D14+'P001'!$E14+'P001'!$F14+'P001'!$G14+'P001'!$H14+'P001'!$I14+'P001'!$J14) -> 0 | L14: ='P001'!$B14-'P001'!$K14 -> 0
A15: Noviembre | K15: ='P001'!$B15-('P001'!$C15+'P001'!$D15+'P001'!$E15+'P001'!$F15+'P001'!$G15+'P001'!$H15+'P001'!$I15+'P001'!$J15) -> 0 | L15: ='P001'!$B15-'P001'!$K15 -> 0
A16: Diciembre | K16: ='P001'!$B16-('P001'!$C16+'P001'!$D16+'P001'!$E16+'P001'!$F16+'P001'!$G16+'P001'!$H16+'P001'!$I16+'P001'!$J16) -> 0 | L16: ='P001'!$B16-'P001'!$K16 -> 0
A18: NRO DE RECIBOS DE LOS PAGOS
C19: RECIBO 1 | D19: RECIBO 2 | E19: RECIBO 3 | F19: RECIBO 4 | G19: RECIBO 5 | H19: RECIBO 6 | I19: RECIBO 7 | J19: RECIBO 8
A20: Enero | C20: 9594
A21: Febrero | C21: 9664
A22: Marzo | C22: 9756
A23: Abril
A24: Mayo
A25: Junio
A26: Julio
A27: Agosto
A28: Septiembre
A29: Octubre
A30: Noviembre
A31: Diciembre

Sheet P004
A1: P004 | C1: DIAS DE FREITAS ADRIAN
A3: PAGOS DEL ALQUILER
B4: COSTO | C4: PAGO 1 | D4: PAGO 2 | E4: PAGO 3 | F4: PAGO 4 | G4: PAGO 5 | H4: PAGO 6 | I4: PAGO 7 | J4: PAGO 8 | K4: SALDO | L4: RECAUDADO
A5: Enero | B5: 128600 | C5: 128600 | K5: ='P004'!$B5-('P004'!$C5+'P004'!$D5+'P004'!$E5+'P004'!$F5+'P004'!$G5+'P004'!$H5+'P004'!$I5+'P004'!$J5) -> 0 | L5: ='P004'!$B5-'P004'!$K5 -> 128600
A6: Febrero | B6: 175000 | C6: 161500 | D6: 13500 | K6: ='P004'!$B6-('P004'!$C6+'P004'!$D6+'P004'!$E6+'P004'!$F6+'P004'!$G6+'P004'!$H6+'P004'!$I6+'P004'!$J6) -> 0 | L6: ='P004'!$B6-'P004'!$K6 -> 175000
A7: Marzo | B7: 175000 | C7: 161500 | D7: 13500 | K7: ='P004'!$B7-('P004'!$C7+'P004'!$D7+'P004'!$E7+'P004'!$F7+'P004'!$G7+'P004'!$H7+'P004'!$I7+'P004'!$J7) -> 0 | L7: ='P004'!$B7-'P004'!$K7 -> 175000
A8: Abril | B8: 175000 | C8: 161500 | D8: 13500 | K8: ='P004'!$B8-('P004'!$C8+'P004'!$D8+'P004'!$E8+'P004'!$F8+'P004'!$G8+'P004'!$H8+'P004'!$I8+'P004'!$J8) -> 0 | L8: ='P004'!$B8-'P004'!$K8 -> 175000
A9: Mayo | B9: 175000 | C9: 115500 | D9: 46000 | E9: 13500 | K9: ='P004'!$B9-('P004'!$C9+'P004'!$D9+'P004'!$E9+'P004'!$F9+'P004'!$G9+'P004'!$H9+'P004'!$I9+'P004'!$J9) -> 0 | L9: ='P004'!$B9-'P004'!$K9 -> 175000
A10: Junio | B10: 175000 | C10: 54000 | D10: 107500 | E10: 13500 | K10: ='P004'!$B10-('P004'!$C10+'P004'!$D10+'P004'!$E10+'P004'!$F10+'P004'!$G10+'P004'!$H10+'P004'!$I10+'P004'!$J10) -> 0 | L10: ='P004'!$B10-'P004'!$K10 -> 175000
A11: Julio | B11: 175000 | C11: 161500 | D11: 13500 | K11: ='P004'!$B11-('P004'!$C11+'P004'!$D11+'P004'!$E11+'P004'!$F11+'P004'!$G11+'P004'!$H11+'P004'!$I11+'P004'!$J11) -> 0 | L11: ='P004'!$B11-'P004'!$K11 -> 175000
A12: Agosto | B12: 175000 | C12: 161500 | D12: 13500 | K12: ='P004'!$B12-('P004'!$C12+'P004'!$D12+'P004'!$E12+'P004'!$F12+'P004'!$G12+'P004'!$H12+'P004'!$I12+'P004'!$J12) -> 0 | L12: ='P004'!$B12-'P004'!$K12 -> 175000
A13: Septiembre | B13: 175000 | C13: 161500 | D13: 13500 | K13: ='P004'!$B13-('P004'!$C13+'P004'!$D13+'P004'!$E13+'P004'!$F13+'P004'!$G13+'P004'!$H13+'P004'!$I13+'P004'!$J13) -> 0 | L13: ='P004'!$B13-'P004'!$K13 -> 175000
A14: Octubre | B14: 175000 | C14: 8000 | D14: 153500 | E14: 13500 | K14: ='P004'!$B14-('P004'!$C14+'P004'!$D14+'P004'!$E14+'P004'!$F14+'P004'!$G14+'P004'!$H14+'P004'!$I14+'P004'!$J14) -> 0 | L14: ='P004'!$B14-'P004'!$K14 -> 175000
A15: Noviembre | B15: 175000 | C15: 11500 | D15: 163500 | K15: ='P004'!$B15-('P004'!$C15+'P004'!$D15+'P004'!$E15+'P004'!$F15+'P004'!$G15+'P004'!$H15+'P004'!$I15+'P004'!$J15) -> 0 | L15: ='P004'!$B15-'P004'!$K15 -> 175000
A16: Diciembre | K16: ='P004'!$B16-('P004'!$C16+'P004'!$D16+'P004'!$E16+'P004'!$F16+'P004'!$G16+'P004'!$H16+'P004'!$I16+'P004'!$J16) -> 0 | L16: ='P004'!$B16-'P004'!$K16 -> 0
A18: NRO DE RECIBOS DE LOS PAGOS
C19: RECIBO 1 | D19: RECIBO 2 | E19: RECIBO 3 | F19: RECIBO 4 | G19: RECIBO 5 | H19: RECIBO 6 | I19: RECIBO 7 | J19: RECIBO 8
A20: Enero | C20: 8708 | D20: 9486
A21: Febrero | C21: 9426 | D21: 9486
A22: Marzo | C22: 9426 | D22: 9486
A23: Abril | C23: 9426 | D23: 9486
A24: Mayo | C24: 9426 | D24: 9436 | E24: 9486
A25: Junio | C25: 9436 | D25: 9476 | E25: 9486
A26: Julio | C26: 9476 | D26: 9486
A27: Agosto | C27: 9476 | D27: 9486
A28: Septiembre | C28: 9476 | D28: 9486
A29: Octubre | C29: 9476 | D29: 9486
A30: Noviembre | C30: 9486
A31: Diciembre
N44: 2900
N46: 3400
N49: 34600
N64: 7602

Sheet P002
A3: PAGOS DEL ALQUILER
B4: COSTO | C4: PAGO 1 | D4: PAGO 2 | E4: PAGO 3 | F4: PAGO 4 | G4: PAGO 5 | H4: PAGO 6 | I4: PAGO 7 | J4: PAGO 8 | K4: SALDO | L4: RECAUDADO
A5: Enero | K5: ='P002'!$B5-('P002'!$C5+'P002'!$D5+'P002'!$E5+'P002'!$F5+'P002'!$G5+'P002'!$H5+'P002'!$I5+'P002'!$J5) -> 0 | L5: ='P002'!$B5-'P002'!$K5 -> 0
A6: Febrero | K6: ='P002'!$B6-('P002'!$C6+'P002'!$D6+'P002'!$E6+'P002'!$F6+'P002'!$G6+'P002'!$H6+'P002'!$I6+'P002'!$J6) -> 0 | L6: ='P002'!$B6-'P002'!$K6 -> 0
A7: Marzo | K7: ='P002'!$B7-('P002'!$C7+'P002'!$D7+'P002'!$E7+'P002'!$F7+'P002'!$G7+'P002'!$H7+'P002'!$I7+'P002'!$J7) -> 0 | L7: ='P002'!$B7-'P002'!$K7 -> 0
A8: Abril | K8: ='P002'!$B8-('P002'!$C8+'P002'!$D8+'P002'!$E8+'P002'!$F8+'P002'!$G8+'P002'!$H8+'P002'!$I8+'P002'!$J8) -> 0 | L8: ='P002'!$B8-'P002'!$K8 -> 0
A9: Mayo | K9: ='P002'!$B9-('P002'!$C9+'P002'!$D9+'P002'!$E9+'P002'!$F9+'P002'!$G9+'P002'!$H9+'P002'!$I9+'P002'!$J9) -> 0 | L9: ='P002'!$B9-'P002'!$K9 -> 0
A10: Junio | K10: ='P002'!$B10-('P002'!$C10+'P002'!$D10+'P002'!$E10+'P002'!$F10+'P002'!$G10+'P002'!$H10+'P002'!$I10+'P002'!$J10) -> 0 | L10: ='P002'!$B10-'P002'!$K10 -> 0
A11: Julio | K11: ='P002'!$B11-('P002'!$C11+'P002'!$D11+'P002'!$E11+'P002'!$F11+'P002'!$G11+'P002'!$H11+'P002'!$I11+'P002'!$J11) -> 0 | L11: ='P002'!$B11-'P002'!$K11 -> 0
A12: Agosto | K12: ='P002'!$B12-('P002'!$C12+'P002'!$D12+'P002'!$E12+'P002'!$F12+'P002'!$G12+'P002'!$H12+'P002'!$I12+'P002'!$J12) -> 0 | L12: ='P002'!$B12-'P002'!$K12 -> 0
A13: Septiembre | K13: ='P002'!$B13-('P002'!$C13+'P002'!$D13+'P002'!$E13+'P002'!$F13+'P002'!$G13+'P002'!$H13+'P002'!$I13+'P002'!$J13) -> 0 | L13: ='P002'!$B13-'P002'!$K13 -> 0
A14: Octubre | K14: ='P002'!$B14-('P002'!$C14+'P002'!$D14+'P002'!$E14+'P002'!$F14+'P002'!$G14+'P002'!$H14+'P002'!$I14+'P002'!$J14) -> 0 | L14: ='P002'!$B14-'P002'!$K14 -> 0
A15: Noviembre | K15: ='P002'!$B15-('P002'!$C15+'P002'!$D15+'P002'!$E15+'P002'!$F15+'P002'!$G15+'P002'!$H15+'P002'!$I15+'P002'!$J15) -> 0 | L15: ='P002'!$B15-'P002'!$K15 -> 0
A16: Diciembre | K16: ='P002'!$B16-('P002'!$C16+'P002'!$D16+'P002'!$E16+'P002'!$F16+'P002'!$G16+'P002'!$H16+'P002'!$I16+'P002'!$J16) -> 0 | L16: ='P002'!$B16-'P002'!$K16 -> 0
A18: NRO DE RECIBOS DE LOS PAGOS
C19: RECIBO 1 | D19: RECIBO 2 | E19: RECIBO 3 | F19: RECIBO 4 | G19: RECIBO 5 | H19: RECIBO 6 | I19: RECIBO 7 | J19: RECIBO 8
A20: Enero
A21: Febrero
A22: Marzo
A23: Abril
A24: Mayo
A25: Junio
A26: Julio
A27: Agosto
A28: Septiembre
A29: Octubre
A30: Noviembre
A31: Diciembre

Sheet P003
A3: PAGOS DEL ALQUILER
B4: COSTO | C4: PAGO 1 | D4: PAGO 2 | E4: PAGO 3 | F4: PAGO 4 | G4: PAGO 5 | H4: PAGO 6 | I4: PAGO 7 | J4: PAGO 8 | K4: SALDO | L4: RECAUDADO
A5: Enero | K5: ='P003'!$B5-('P003'!$C5+'P003'!$D5+'P003'!$E5+'P003'!$F5+'P003'!$G5+'P003'!$H5+'P003'!$I5+'P003'!$J5) -> 0 | L5: ='P003'!$B5-'P003'!$K5 -> 0
A6: Febrero | K6: ='P003'!$B6-('P003'!$C6+'P003'!$D6+'P003'!$E6+'P003'!$F6+'P003'!$G6+'P003'!$H6+'P003'!$I6+'P003'!$J6) -> 0 | L6: ='P003'!$B6-'P003'!$K6 -> 0
A7: Marzo | K7: ='P003'!$B7-('P003'!$C7+'P003'!$D7+'P003'!$E7+'P003'!$F7+'P003'!$G7+'P003'!$H7+'P003'!$I7+'P003'!$J7) -> 0 | L7: ='P003'!$B7-'P003'!$K7 -> 0
A8: Abril | K8: ='P003'!$B8-('P003'!$C8+'P003'!$D8+'P003'!$E8+'P003'!$F8+'P003'!$G8+'P003'!$H8+'P003'!$I8+'P003'!$J8) -> 0 | L8: ='P003'!$B8-'P003'!$K8 -> 0
A9: Mayo | K9: ='P003'!$B9-('P003'!$C9+'P003'!$D9+'P003'!$E9+'P003'!$F9+'P003'!$G9+'P003'!$H9+'P003'!$I9+'P003'!$J9) -> 0 | L9: ='P003'!$B9-'P003'!$K9 -> 0
A10: Junio | K10: ='P003'!$B10-('P003'!$C10+'P003'!$D10+'P003'!$E10+'P003'!$F10+'P003'!$G10+'P003'!$H10+'P003'!$I10+'P003'!$J10) -> 0 | L10: ='P003'!$B10-'P003'!$K10 -> 0
A11: Julio | K11: ='P003'!$B11-('P003'!$C11+'P003'!$D11+'P003'!$E11+'P003'!$F11+'P003'!$G11+'P003'!$H11+'P003'!$I11+'P003'!$J11) -> 0 | L11: ='P003'!$B11-'P003'!$K11 -> 0
A12: Agosto | K12: ='P003'!$B12-('P003'!$C12+'P003'!$D12+'P003'!$E12+'P003'!$F12+'P003'!$G12+'P003'!$H12+'P003'!$I12+'P003'!$J12) -> 0 | L12: ='P003'!$B12-'P003'!$K12 -> 0
A13: Septiembre | K13: ='P003'!$B13-('P003'!$C13+'P003'!$D13+'P003'!$E13+'P003'!$F13+'P003'!$G13+'P003'!$H13+'P003'!$I13+'P003'!$J13) -> 0 | L13: ='P003'!$B13-'P003'!$K13 -> 0
A14: Octubre | K14: ='P003'!$B14-('P003'!$C14+'P003'!$D14+'P003'!$E14+'P003'!$F14+'P003'!$G14+'P003'!$H14+'P003'!$I14+'P003'!$J14) -> 0 | L14: ='P003'!$B14-'P003'!$K14 -> 0
A15: Noviembre | K15: ='P003'!$B15-('P003'!$C15+'P003'!$D15+'P003'!$E15+'P003'!$F15+'P003'!$G15+'P003'!$H15+'P003'!$I15+'P003'!$J15) -> 0 | L15: ='P003'!$B15-'P003'!$K15 -> 0
A16: Diciembre | K16: ='P003'!$B16-('P003'!$C16+'P003'!$D16+'P003'!$E16+'P003'!$F16+'P003'!$G16+'P003'!$H16+'P003'!$I16+'P003'!$J16) -> 0 | L16: ='P003'!$B16-'P003'!$K16 -> 0
A18: NRO DE RECIBOS DE LOS PAGOS
C19: RECIBO 1 | D19: RECIBO 2 | E19: RECIBO 3 | F19: RECIBO 4 | G19: RECIBO 5 | H19: RECIBO 6 | I19: RECIBO 7 | J19: RECIBO 8
A20: Enero
A21: Febrero
A22: Marzo
A23: Abril
A24: Mayo
A25: Junio
A26: Julio
A27: Agosto
A28: Septiembre
A29: Octubre
A30: Noviembre
A31: Diciembre

Sheet P005
A1: P005 | C1: URSULA HUBER
A3: PAGOS DEL ALQUILER
B4: 177600 | C4: PAGO 1 | D4: PAGO 2 | E4: PAGO 3 | F4: PAGO 4 | G4: PAGO 5 | H4: PAGO 6 | I4: PAGO 7 | J4: PAGO 8 | K4: SALDO | L4: RECAUDADO
A5: Enero | B5: 177600 | C5: 177600 | K5: ='P005'!$B5-('P005'!$C5+'P005'!$D5+'P005'!$E5+'P005'!$F5+'P005'!$G5+'P005'!$H5+'P005'!$I5+'P005'!$J5) -> 0 | L5: ='P005'!$B5-'P005'!$K5 -> 177600 | M5: 13500
A6: Febrero | B6: 177600 | C6: 177600 | K6: ='P005'!$B6-('P005'!$C6+'P005'!$D6+'P005'!$E6+'P005'!$F6+'P005'!$G6+'P005'!$H6+'P005'!$I6+'P005'!$J6) -> 0 | L6: ='P005'!$B6-'P005'!$K6 -> 177600 | M6: 13500
A7: Marzo | K7: ='P005'!$B7-('P005'!$C7+'P005'!$D7+'P005'!$E7+'P005'!$F7+'P005'!$G7+'P005'!$H7+'P005'!$I7+'P005'!$J7) -> 0 | L7: ='P005'!$B7-'P005'!$K7 -> 0
A8: Abril | K8: ='P005'!$B8-('P005'!$C8+'P005'!$D8+'P005'!$E8+'P005'!$F8+'P005'!$G8+'P005'!$H8+'P005'!$I8+'P005'!$J8) -> 0 | L8: ='P005'!$B8-'P005'!$K8 -> 0
A9: Mayo | K9: ='P005'!$B9-('P005'!$C9+'P005'!$D9+'P005'!$E9+'P005'!$F9+'P005'!$G9+'P005'!$H9+'P005'!$I9+'P005'!$J9) -> 0 | L9: ='P005'!$B9-'P005'!$K9 -> 0
A10: Junio | K10: ='P005'!$B10-('P005'!$C10+'P005'!$D10+'P005'!$E10+'P005'!$F10+'P005'!$G10+'P005'!$H10+'P005'!$I10+'P005'!$J10) -> 0 | L10: ='P005'!$B10-'P005'!$K10 -> 0
A11: Julio | K11: ='P005'!$B11-('P005'!$C11+'P005'!$D11+'P005'!$E11+'P005'!$F11+'P005'!$G11+'P005'!$H11+'P005'!$I11+'P005'!$J11) -> 0 | L11: ='P005'!$B11-'P005'!$K11 -> 0
A12: Agosto | K12: ='P005'!$B12-('P005'!$C12+'P005'!$D12+'P005'!$E12+'P005'!$F12+'P005'!$G12+'P005'!$H12+'P005'!$I12+'P005'!$J12) -> 0 | L12: ='P005'!$B12-'P005'!$K12 -> 0
A13: Septiembre | K13: ='P005'!$B13-('P005'!$C13+'P005'!$D13+'P005'!$E13+'P005'!$F13+'P005'!$G13+'P005'!$H13+'P005'!$I13+'P005'!$J13) -> 0 | L13: ='P005'!$B13-'P005'!$K13 -> 0
A14: Octubre | K14: ='P005'!$B14-('P005'!$C14+'P005'!$D14+'P005'!$E14+'P005'!$F14+'P005'!$G14+'P005'!$H14+'P005'!$I14+'P005'!$J14) -> 0 | L14: ='P005'!$B14-'P005'!$K14 -> 0
A15: Noviembre | K15: ='P005'!$B15-('P005'!$C15+'P005'!$D15+'P005'!$E15+'P005'!$F15+'P005'!$G15+'P005'!$H15+'P005'!$I15+'P005'!$J15) -> 0 | L15: ='P005'!$B15-'P005'!$K15 -> 0
A16: Diciembre | K16: ='P005'!$B16-('P005'!$C16+'P005'!$D16+'P005'!$E16+'P005'!$F16+'P005'!$G16+'P005'!$H16+'P005'!$I16+'P005'!$J16) -> 0 | L16: ='P005'!$B16-'P005'!$K16 -> 0
A18: NRO DE RECIBOS DE LOS PAGOS
C19: RECIBO 1 | D19: RECIBO 2 | E19: RECIBO 3 | F19: RECIBO 4 | G19: RECIBO 5 | H19: RECIBO 6 | I19: RECIBO 7 | J19: RECIBO 8
A20: Enero | C20: 9598
A21: Febrero | C21: 9703
A22: Marzo
A23: Abril
A24: Mayo
A25: Junio
A26: Julio
A27: Agosto
A28: Septiembre
A29: Octubre
A30: Noviembre
A31: Diciembre

Sheet P006
A1: P6 | C1: ROSALINA FERNANDEZ
A3: PAGOS DEL ALQUILER
B4: 177600 | C4: PAGO 1 | D4: PAGO 2 | E4: PAGO 3 | F4: PAGO 4 | G4: PAGO 5 | H4: PAGO 6 | I4: PAGO 7 | J4: PAGO 8 | K4: SALDO | L4: RECAUDADO
A5: Enero | B5: 177600 | C5: 177600 | K5: ='P006'!$B5-('P006'!$C5+'P006'!$D5+'P006'!$E5+'P006'!$F5+'P006'!$G5+'P006'!$H5+'P006'!$I5+'P006'!$J5) -> 0 | L5: ='P006'!$B5-'P006'!$K5 -> 177600 | M5: 13500
A6: Febrero | B6: 177600 | C6: 177600 | K6: ='P006'!$B6-('P006'!$C6+'P006'!$D6+'P006'!$E6+'P006'!$F6+'P006'!$G6+'P006'!$H6+'P006'!$I6+'P006'!$J6) -> 0 | L6: ='P006'!$B6-'P006'!$K6 -> 177600 | M6: 13500
A7: Marzo | K7: ='P006'!$B7-('P006'!$C7+'P006'!$D7+'P006'!$E7+'P006'!$F7+'P006'!$G7+'P006'!$H7+'P006'!$I7+'P006'!$J7) -> 0 | L7: ='P006'!$B7-'P006'!$K7 -> 0
A8: Abril | K8: ='P006'!$B8-('P006'!$C8+'P006'!$D8+'P006'!$E8+'P006'!$F8+'P006'!$G8+'P006'!$H8+'P006'!$I8+'P006'!$J8) -> 0 | L8: ='P006'!$B8-'P006'!$K8 -> 0
A9: Mayo | K9: ='P006'!$B9-('P006'!$C9+'P006'!$D9+'P006'!$E9+'P006'!$F9+'P006'!$G9+'P006'!$H9+'P006'!$I9+'P006'!$J9) -> 0 | L9: ='P006'!$B9-'P006'!$K9 -> 0
A10: Junio | K10: ='P006'!$B10-('P006'!$C10+'P006'!$D10+'P006'!$E10+'P006'!$F10+'P006'!$G10+'P006'!$H10+'P006'!$I10+'P006'!$J10) -> 0 | L10: ='P006'!$B10-'P006'!$K10 -> 0
A11: Julio | K11: ='P006'!$B11-('P006'!$C11+'P006'!$D11+'P006'!$E11+'P006'!$F11+'P006'!$G11+'P006'!$H11+'P006'!$I11+'P006'!$J11) -> 0 | L11: ='P006'!$B11-'P006'!$K11 -> 0
A12: Agosto | K12: ='P006'!$B12-('P006'!$C12+'P006'!$D12+'P006'!$E12+'P006'!$F12+'P006'!$G12+'P006'!$H12+'P006'!$I12+'P006'!$J12) -> 0 | L12: ='P006'!$B12-'P006'!$K12 -> 0
A13: Septiembre | K13: ='P006'!$B13-('P006'!$C13+'P006'!$D13+'P006'!$E13+'P006'!$F13+'P006'!$G13+'P006'!$H13+'P006'!$I13+'P006'!$J13) -> 0 | L13: ='P006'!$B13-'P006'!$K13 -> 0
A14: Octubre | K14: ='P006'!$B14-('P006'!$C14+'P006'!$D14+'P006'!$E14+'P006'!$F14+'P006'!$G14+'P006'!$H14+'P006'!$I14+'P006'!$J14) -> 0 | L14: ='P006'!$B14-'P006'!$K14 -> 0
A15: Noviembre | K15: ='P006'!$B15-('P006'!$C15+'P006'!$D15+'P006'!$E15+'P006'!$F15+'P006'!$G15+'P006'!$H15+'P006'!$I15+'P006'!$J15) -> 0 | L15: ='P006'!$B15-'P006'!$K15 -> 0
A16: Diciembre | K16: ='P006'!$B16-('P006'!$C16+'P006'!$D16+'P006'!$E16+'P006'!$F16+'P006'!$G16+'P006'!$H16+'P006'!$I16+'P006'!$J16) -> 0 | L16: ='P006'!$B16-'P006'!$K16 -> 0
A18: NRO DE RECIBOS DE LOS PAGOS
C19: RECIBO 1 | D19: RECIBO 2 | E19: RECIBO 3 | F19: RECIBO 4 | G19: RECIBO 5 | H19: RECIBO 6 | I19: RECIBO 7 | J19: RECIBO 8
A20: Enero | C20: 9636
A21: Febrero | C21: 9706
A22: Marzo
A23: Abril
A24: Mayo
A25: Junio
A26: Julio
A27: Agosto
A28: Septiembre
A29: Octubre
A30: Noviembre
A31: Diciembre

Sheet P007
A3: PAGOS DEL ALQUILER
B4: COSTO | C4: PAGO 1 | D4: PAGO 2 | E4: PAGO 3 | F4: PAGO 4 | G4: PAGO 5 | H4: PAGO 6 | I4: PAGO 7 | J4: PAGO 8 | K4: SALDO | L4: RECAUDADO
A5: Enero | K5: ='P007'!$B5-('P007'!$C5+'P007'!$D5+'P007'!$E5+'P007'!$F5+'P007'!$G5+'P007'!$H5+'P007'!$I5+'P007'!$J5) -> 0 | L5: ='P007'!$B5-'P007'!$K5 -> 0
A6: Febrero | K6: ='P007'!$B6-('P007'!$C6+'P007'!$D6+'P007'!$E6+'P007'!$F6+'P007'!$G6+'P007'!$H6+'P007'!$I6+'P007'!$J6) -> 0 | L6: ='P007'!$B6-'P007'!$K6 -> 0
A7: Marzo | K7: ='P007'!$B7-('P007'!$C7+'P007'!$D7+'P007'!$E7+'P007'!$F7+'P007'!$G7+'P007'!$H7+'P007'!$I7+'P007'!$J7) -> 0 | L7: ='P007'!$B7-'P007'!$K7 -> 0
A8: Abril | K8: ='P007'!$B8-('P007'!$C8+'P007'!$D8+'P007'!$E8+'P007'!$F8+'P007'!$G8+'P007'!$H8+'P007'!$I8+'P007'!$J8) -> 0 | L8: ='P007'!$B8-'P007'!$K8 -> 0
A9: Mayo | K9: ='P007'!$B9-('P007'!$C9+'P007'!$D9+'P007'!$E9+'P007'!$F9+'P007'!$G9+'P007'!$H9+'P007'!$I9+'P007'!$J9) -> 0 | L9: ='P007'!$B9-'P007'!$K9 -> 0
A10: Junio | K10: ='P007'!$B10-('P007'!$C10+'P007'!$D10+'P007'!$E10+'P007'!$F10+'P007'!$G10+'P007'!$H10+'P007'!$I10+'P007'!$J10) -> 0 | L10: ='P007'!$B10-'P007'!$K10 -> 0
A11: Julio | K11: ='P007'!$B11-('P007'!$C11+'P007'!$D11+'P007'!$E11+'P007'!$F11+'P007'!$G11+'P007'!$H11+'P007'!$I11+'P007'!$J11) -> 0 | L11: ='P007'!$B11-'P007'!$K11 -> 0
A12: Agosto | K12: ='P007'!$B12-('P007'!$C12+'P007'!$D12+'P007'!$E12+'P007'!$F12+'P007'!$G12+'P007'!$H12+'P007'!$I12+'P007'!$J12) -> 0 | L12: ='P007'!$B12-'P007'!$K12 -> 0
A13: Septiembre | K13: ='P007'!$B13-('P007'!$C13+'P007'!$D13+'P007'!$E13+'P007'!$F13+'P007'!$G13+'P007'!$H13+'P007'!$I13+'P007'!$J13) -> 0 | L13: ='P007'!$B13-'P007'!$K13 -> 0
A14: Octubre | K14: ='P007'!$B14-('P007'!$C14+'P007'!$D14+'P007'!$E14+'P007'!$F14+'P007'!$G14+'P007'!$H14+'P007'!$I14+'P007'!$J14) -> 0 | L14: ='P007'!$B14-'P007'!$K14 -> 0
A15: Noviembre | K15: ='P007'!$B15-('P007'!$C15+'P007'!$D15+'P007'!$E15+'P007'!$F15+'P007'!$G15+'P007'!$H15+'P007'!$I15+'P007'!$J15) -> 0 | L15: ='P007'!$B15-'P007'!$K15 -> 0
A16: Diciembre | K16: ='P007'!$B16-('P007'!$C16+'P007'!$D16+'P007'!$E16+'P007'!$F16+'P007'!$G16+'P007'!$H16+'P007'!$I16+'P007'!$J16) -> 0 | L16: ='P007'!$B16-'P007'!$K16 -> 0
A18: NRO DE RECIBOS DE LOS PAGOS
C19: RECIBO 1 | D19: RECIBO 2 | E19: RECIBO 3 | F19: RECIBO 4 | G19: RECIBO 5 | H19: RECIBO 6 | I19: RECIBO 7 | J19: RECIBO 8
A20: Enero
A21: Febrero
A22: Marzo
A23: Abril
A24: Mayo
A25: Junio
A26: Julio
A27: Agosto
A28: Septiembre
A29: Octubre
A30: Noviembre
A31: Diciembre

Sheet P009
A1: P.9 | C1: ACOSTA EVANY
A3: PAGOS DEL ALQUILER
B4: 177600 | C4: PAGO 1 | D4: PAGO 2 | E4: PAGO 3 | F4: PAGO 4 | G4: PAGO 5 | H4: PAGO 6 | I4: PAGO 7 | J4: PAGO 8 | K4: SALDO | L4: RECAUDADO
A5: Enero | B5: 177600 | C5: 177600 | K5: ='P009'!$B5-('P009'!$C5+'P009'!$D5+'P009'!$E5+'P009'!$F5+'P009'!$G5+'P009'!$H5+'P009'!$I5+'P009'!$J5) -> 0 | L5: ='P009'!$B5-'P009'!$K5 -> 177600 | M5: 13500
A6: Febrero | B6: 177600 | C6: 177600 | K6: ='P009'!$B6-('P009'!$C6+'P009'!$D6+'P009'!$E6+'P009'!$F6+'P009'!$G6+'P009'!$H6+'P009'!$I6+'P009'!$J6) -> 0 | L6: ='P009'!$B6-'P009'!$K6 -> 177600 | M6: 13500
A7: Marzo | B7: 193200 | C7: 193200 | K7: ='P009'!$B7-('P009'!$C7+'P009'!$D7+'P009'!$E7+'P009'!$F7+'P009'!$G7+'P009'!$H7+'P009'!$I7+'P009'!$J7) -> 0 | L7: ='P009'!$B7-'P009'!$K7 -> 193200 | M7: 13500
A8: Abril | B8: 193200 | K8: ='P009'!$B8-('P009'!$C8+'P009'!$D8+'P009'!$E8+'P009'!$F8+'P009'!$G8+'P009'!$H8+'P009'!$I8+'P009'!$J8) -> 193200 | L8: ='P009'!$B8-'P009'!$K8 -> 0
A9: Mayo | K9: ='P009'!$B9-('P009'!$C9+'P009'!$D9+'P009'!$E9+'P009'!$F9+'P009'!$G9+'P009'!$H9+'P009'!$I9+'P009'!$J9) -> 0 | L9: ='P009'!$B9-'P009'!$K9 -> 0
A10: Junio | K10: ='P009'!$B10-('P009'!$C10+'P009'!$D10+'P009'!$E10+'P009'!$F10+'P009'!$G10+'P009'!$H10+'P009'!$I10+'P009'!$J10) -> 0 | L10: ='P009'!$B10-'P009'!$K10 -> 0
A11: Julio | K11: ='P009'!$B11-('P009'!$C11+'P009'!$D11+'P009'!$E11+'P009'!$F11+'P009'!$G11+'P009'!$H11+'P009'!$I11+'P009'!$J11) -> 0 | L11: ='P009'!$B11-'P009'!$K11 -> 0
A12: Agosto | K12: ='P009'!$B12-('P009'!$C12+'P009'!$D12+'P009'!$E12+'P009'!$F12+'P009'!$G12+'P009'!$H12+'P009'!$I12+'P009'!$J12) -> 0 | L12: ='P009'!$B12-'P009'!$K12 -> 0
A13: Septiembre | K13: ='P009'!$B13-('P009'!$C13+'P009'!$D13+'P009'!$E13+'P009'!$F13+'P009'!$G13+'P009'!$H13+'P009'!$I13+'P009'!$J13) -> 0 | L13: ='P009'!$B13-'P009'!$K13 -> 0
A14: Octubre | K14: ='P009'!$B14-('P009'!$C14+'P009'!$D14+'P009'!$E14+'P009'!$F14+'P009'!$G14+'P009'!$H14+'P009'!$I14+'P009'!$J14) -> 0 | L14: ='P009'!$B14-'P009'!$K14 -> 0
A15: Noviembre | K15: ='P009'!$B15-('P009'!$C15+'P009'!$D15+'P009'!$E15+'P009'!$F15+'P009'!$G15+'P009'!$H15+'P009'!$I15+'P009'!$J15) -> 0 | L15: ='P009'!$B15-'P009'!$K15 -> 0
A16: Diciembre | K16: ='P009'!$B16-('P009'!$C16+'P009'!$D16+'P009'!$E16+'P009'!$F16+'P009'!$G16+'P009'!$H16+'P009'!$I16+'P009'!$J16) -> 0 | L16: ='P009'!$B16-'P009'!$K16 -> 0
A18: NRO DE RECIBOS DE LOS PAGOS
C19: RECIBO 1 | D19: RECIBO 2 | E19: RECIBO 3 | F19: RECIBO 4 | G19: RECIBO 5 | H19: RECIBO 6 | I19: RECIBO 7 | J19: RECIBO 8
A20: Enero | C20: 9627
A21: Febrero | C21: 9679
A22: Marzo | C22: 6757
A23: Abril
A24: Mayo
A25: Junio
A26: Julio
A27: Agosto
A28: Septiembre
A29: Octubre
A30: Noviembre
A31: Diciembre

Sheet P008
A1: 8 | C1: RUIZ PAOLA
A3: PAGOS DEL ALQUILER
B4: COSTO | C4: PAGO 1 | D4: PAGO 2 | E4: PAGO 3 | F4: PAGO 4 | G4: PAGO 5 | H4: PAGO 6 | I4: PAGO 7 | J4: PAGO 8 | K4: SALDO | L4: RECAUDADO
A5: Enero | B5: 355300 | C5: 355300 | K5: ='P008'!$B5-('P008'!$C5+'P008'!$D5+'P008'!$E5+'P008'!$F5+'P008'!$G5+'P008'!$H5+'P008'!$I5+'P008'!$J5) -> 0 | L5: ='P008'!$B5-'P008'!$K5 -> 355300 | M5: 13500
A6: Febrero | B6: 355300 | C6: 355300 | K6: ='P008'!$B6-('P008'!$C6+'P008'!$D6+'P008'!$E6+'P008'!$F6+'P008'!$G6+'P008'!$H6+'P008'!$I6+'P008'!$J6) -> 0 | L6: ='P008'!$B6-'P008'!$K6 -> 355300 | M6: 13500
A7: Marzo | B7: 386600 | C7: 346500 | K7: ='P008'!$B7-('P008'!$C7+'P008'!$D7+'P008'!$E7+'P008'!$F7+'P008'!$G7+'P008'!$H7+'P008'!$I7+'P008'!$J7) -> 40100 | L7: ='P008'!$B7-'P008'!$K7 -> 346500 | M7: 13500
A8: Abril | K8: ='P008'!$B8-('P008'!$C8+'P008'!$D8+'P008'!$E8+'P008'!$F8+'P008'!$G8+'P008'!$H8+'P008'!$I8+'P008'!$J8) -> 0 | L8: ='P008'!$B8-'P008'!$K8 -> 0
A9: Mayo | K9: ='P008'!$B9-('P008'!$C9+'P008'!$D9+'P008'!$E9+'P008'!$F9+'P008'!$G9+'P008'!$H9+'P008'!$I9+'P008'!$J9) -> 0 | L9: ='P008'!$B9-'P008'!$K9 -> 0
A10: Junio | K10: ='P008'!$B10-('P008'!$C10+'P008'!$D10+'P008'!$E10+'P008'!$F10+'P008'!$G10+'P008'!$H10+'P008'!$I10+'P008'!$J10) -> 0 | L10: ='P008'!$B10-'P008'!$K10 -> 0
A11: Julio | K11: ='P008'!$B11-('P008'!$C11+'P008'!$D11+'P008'!$E11+'P008'!$F11+'P008'!$G11+'P008'!$H11+'P008'!$I11+'P008'!$J11) -> 0 | L11: ='P008'!$B11-'P008'!$K11 -> 0
A12: Agosto | K12: ='P008'!$B12-('P008'!$C12+'P008'!$D12+'P008'!$E12+'P008'!$F12+'P008'!$G12+'P008'!$H12+'P008'!$I12+'P008'!$J12) -> 0 | L12: ='P008'!$B12-'P008'!$K12 -> 0
A13: Septiembre | K13: ='P008'!$B13-('P008'!$C13+'P008'!$D13+'P008'!$E13+'P008'!$F13+'P008'!$G13+'P008'!$H13+'P008'!$I13+'P008'!$J13) -> 0 | L13: ='P008'!$B13-'P008'!$K13 -> 0
A14: Octubre | K14: ='P008'!$B14-('P008'!$C14+'P008'!$D14+'P008'!$E14+'P008'!$F14+'P008'!$G14+'P008'!$H14+'P008'!$I14+'P008'!$J14) -> 0 | L14: ='P008'!$B14-'P008'!$K14 -> 0
A15: Noviembre | K15: ='P008'!$B15-('P008'!$C15+'P008'!$D15+'P008'!$E15+'P008'!$F15+'P008'!$G15+'P008'!$H15+'P008'!$I15+'P008'!$J15) -> 0 | L15: ='P008'!$B15-'P008'!$K15 -> 0
A16: Diciembre | K16: ='P008'!$B16-('P008'!$C16+'P008'!$D16+'P008'!$E16+'P008'!$F16+'P008'!$G16+'P008'!$H16+'P008'!$I16+'P008'!$J16) -> 0 | L16: ='P008'!$B16-'P008'!$K16 -> 0
A18: NRO DE RECIBOS DE LOS PAGOS
C19: RECIBO 1 | D19: RECIBO 2 | E19: RECIBO 3 | F19: RECIBO 4 | G19: RECIBO 5 | H19: RECIBO 6 | I19: RECIBO 7 | J19: RECIBO 8
A20: Enero | C20: 9607
A21: Febrero | C21: 9665
A22: Marzo | C22: 9730
A23: Abril
A24: Mayo
A25: Junio
A26: Julio
A27: Agosto
A28: Septiembre
A29: Octubre
A30: Noviembre
A31: Diciembre

Sheet P010
A1: Pto 10/11/125 | C1: FERREIRA ISABELLA
A3: PAGOS DEL ALQUILER
B4: COSTO | C4: PAGO 1 | D4: PAGO 2 | E4: PAGO 3 | F4: PAGO 4 | G4: PAGO 5 | H4: PAGO 6 | I4: PAGO 7 | J4: PAGO 8 | K4: SALDO | L4: RECAUDADO
A5: Enero | B5: 579700 | K5: ='P010'!$B5-('P010'!$C5+'P010'!$D5+'P010'!$E5+'P010'!$F5+'P010'!$G5+'P010'!$H5+'P010'!$I5+'P010'!$J5) -> 579700 | L5: ='P010'!$B5-'P010'!$K5 -> 0
A6: Febrero | B6: 579700 | K6: ='P010'!$B6-('P010'!$C6+'P010'!$D6+'P010'!$E6+'P010'!$F6+'P010'!$G6+'P010'!$H6+'P010'!$I6+'P010'!$J6) -> 579700 | L6: ='P010'!$B6-'P010'!$K6 -> 0 | O6: 26000
A7: Marzo | B7: 579700 | K7: ='P010'!$B7-('P010'!$C7+'P010'!$D7+'P010'!$E7+'P010'!$F7+'P010'!$G7+'P010'!$H7+'P010'!$I7+'P010'!$J7) -> 579700 | L7: ='P010'!$B7-'P010'!$K7 -> 0
A8: Abril | B8: 579700 | K8: ='P010'!$B8-('P010'!$C8+'P010'!$D8+'P010'!$E8+'P010'!$F8+'P010'!$G8+'P010'!$H8+'P010'!$I8+'P010'!$J8) -> 579700 | L8: ='P010'!$B8-'P010'!$K8 -> 0
A9: Mayo | B9: 579700 | K9: ='P010'!$B9-('P010'!$C9+'P010'!$D9+'P010'!$E9+'P010'!$F9+'P010'!$G9+'P010'!$H9+'P010'!$I9+'P010'!$J9) -> 579700 | L9: ='P010'!$B9-'P010'!$K9 -> 0
A10: Junio | K10: ='P010'!$B10-('P010'!$C10+'P010'!$D10+'P010'!$E10+'P010'!$F10+'P010'!$G10+'P010'!$H10+'P010'!$I10+'P010'!$J10) -> 0 | L10: ='P010'!$B10-'P010'!$K10 -> 0
A11: Julio | K11: ='P010'!$B11-('P010'!$C11+'P010'!$D11+'P010'!$E11+'P010'!$F11+'P010'!$G11+'P010'!$H11+'P010'!$I11+'P010'!$J11) -> 0 | L11: ='P010'!$B11-'P010'!$K11 -> 0
A12: Agosto | K12: ='P010'!$B12-('P010'!$C12+'P010'!$D12+'P010'!$E12+'P010'!$F12+'P010'!$G12+'P010'!$H12+'P010'!$I12+'P010'!$J12) -> 0 | L12: ='P010'!$B12-'P010'!$K12 -> 0
A13: Septiembre | K13: ='P010'!$B13-('P010'!$C13+'P010'!$D13+'P010'!$E13+'P010'!$F13+'P010'!$G13+'P010'!$H13+'P010'!$I13+'P010'!$J13) -> 0 | L13: ='P010'!$B13-'P010'!$K13 -> 0
A14: Octubre | K14: ='P010'!$B14-('P010'!$C14+'P010'!$D14+'P010'!$E14+'P010'!$F14+'P010'!$G14+'P010'!$H14+'P010'!$I14+'P010'!$J14) -> 0 | L14: ='P010'!$B14-'P010'!$K14 -> 0
A15: Noviembre | K15: ='P010'!$B15-('P010'!$C15+'P010'!$D15+'P010'!$E15+'P010'!$F15+'P010'!$G15+'P010'!$H15+'P010'!$I15+'P010'!$J15) -> 0 | L15: ='P010'!$B15-'P010'!$K15 -> 0
A16: Diciembre | K16: ='P010'!$B16-('P010'!$C16+'P010'!$D16+'P010'!$E16+'P010'!$F16+'P010'!$G16+'P010'!$H16+'P010'!$I16+'P010'!$J16) -> 0 | L16: ='P010'!$B16-'P010'!$K16 -> 0
A18: NRO DE RECIBOS DE LOS PAGOS
C19: RECIBO 1 | D19: RECIBO 2 | E19: RECIBO 3 | F19: RECIBO 4 | G19: RECIBO 5 | H19: RECIBO 6 | I19: RECIBO 7 | J19: RECIBO 8
A20: Enero
A21: Febrero
A22: Marzo
A23: Abril
A24: Mayo
A25: Junio
A26: Julio
A27: Agosto
A28: Septiembre
A29: Octubre
A30: Noviembre
A31: Diciembre

Sheet P011
A3: PAGOS DEL ALQUILER
B4: COSTO | C4: PAGO 1 | D4: PAGO 2 | E4: PAGO 3 | F4: PAGO 4 | G4: PAGO 5 | H4: PAGO 6 | I4: PAGO 7 | J4: PAGO 8 | K4: SALDO | L4: RECAUDADO
A5: Enero | K5: ='P011'!$B5-('P011'!$C5+'P011'!$D5+'P011'!$E5+'P011'!$F5+'P011'!$G5+'P011'!$H5+'P011'!$I5+'P011'!$J5) -> 0 | L5: ='P011'!$B5-'P011'!$K5 -> 0
A6: Febrero | K6: ='P011'!$B6-('P011'!$C6+'P011'!$D6+'P011'!$E6+'P011'!$F6+'P011'!$G6+'P011'!$H6+'P011'!$I6+'P011'!$J6) -> 0 | L6: ='P011'!$B6-'P011'!$K6 -> 0
A7: Marzo | K7: ='P011'!$B7-('P011'!$C7+'P011'!$D7+'P011'!$E7+'P011'!$F7+'P011'!$G7+'P011'!$H7+'P011'!$I7+'P011'!$J7) -> 0 | L7: ='P011'!$B7-'P011'!$K7 -> 0
A8: Abril | K8: ='P011'!$B8-('P011'!$C8+'P011'!$D8+'P011'!$E8+'P011'!$F8+'P011'!$G8+'P011'!$H8+'P011'!$I8+'P011'!$J8) -> 0 | L8: ='P011'!$B8-'P011'!$K8 -> 0
A9: Mayo | K9: ='P011'!$B9-('P011'!$C9+'P011'!$D9+'P011'!$E9+'P011'!$F9+'P011'!$G9+'P011'!$H9+'P011'!$I9+'P011'!$J9) -> 0 | L9: ='P011'!$B9-'P011'!$K9 -> 0
A10: Junio | K10: ='P011'!$B10-('P011'!$C10+'P011'!$D10+'P011'!$E10+'P011'!$F10+'P011'!$G10+'P011'!$H10+'P011'!$I10+'P011'!$J10) -> 0 | L10: ='P011'!$B10-'P011'!$K10 -> 0
A11: Julio | K11: ='P011'!$B11-('P011'!$C11+'P011'!$D11+'P011'!$E11+'P011'!$F11+'P011'!$G11+'P011'!$H11+'P011'!$I11+'P011'!$J11) -> 0 | L11: ='P011'!$B11-'P011'!$K11 -> 0
A12: Agosto | K12: ='P011'!$B12-('P011'!$C12+'P011'!$D12+'P011'!$E12+'P011'!$F12+'P011'!$G12+'P011'!$H12+'P011'!$I12+'P011'!$J12) -> 0 | L12: ='P011'!$B12-'P011'!$K12 -> 0
A13: Septiembre | K13: ='P011'!$B13-('P011'!$C13+'P011'!$D13+'P011'!$E13+'P011'!$F13+'P011'!$G13+'P011'!$H13+'P011'!$I13+'P011'!$J13) -> 0 | L13: ='P011'!$B13-'P011'!$K13 -> 0
A14: Octubre | K14: ='P011'!$B14-('P011'!$C14+'P011'!$D14+'P011'!$E14+'P011'!$F14+'P011'!$G14+'P011'!$H14+'P011'!$I14+'P011'!$J14) -> 0 | L14: ='P011'!$B14-'P011'!$K14 -> 0
A15: Noviembre | K15: ='P011'!$B15-('P011'!$C15+'P011'!$D15+'P011'!$E15+'P011'!$F15+'P011'!$G15+'P011'!$H15+'P011'!$I15+'P011'!$J15) -> 0 | L15: ='P011'!$B15-'P011'!$K15 -> 0
A16: Diciembre | K16: ='P011'!$B16-('P011'!$C16+'P011'!$D16+'P011'!$E16+'P011'!$F16+'P011'!$G16+'P011'!$H16+'P011'!$I16+'P011'!$J16) -> 0 | L16: ='P011'!$B16-'P011'!$K16 -> 0
A18: NRO DE RECIBOS DE LOS PAGOS
C19: RECIBO 1 | D19: RECIBO 2 | E19: RECIBO 3 | F19: RECIBO 4 | G19: RECIBO 5 | H19: RECIBO 6 | I19: RECIBO 7 | J19: RECIBO 8
A20: Enero
A21: Febrero
A22: Marzo
A23: Abril
A24: Mayo
A25: Junio
A26: Julio
A27: Agosto
A28: Septiembre
A29: Octubre
A30: Noviembre
A31: Diciembre

Sheet P012
A1: P012 | C1: CHUCHI
A3: PAGOS DEL ALQUILER
B4: COSTO | C4: PAGO 1 | D4: PAGO 2 | E4: PAGO 3 | F4: PAGO 4 | G4: PAGO 5 | H4: PAGO 6 | I4: PAGO 7 | J4: PAGO 8 | K4: SALDO | L4: RECAUDADO
A5: Enero | B5: 1821900 | C5: 1821900 | K5: ='P012'!$B5-('P012'!$C5+'P012'!$D5+'P012'!$E5+'P012'!$F5+'P012'!$G5+'P012'!$H5+'P012'!$I5+'P012'!$J5) -> 0 | L5: ='P012'!$B5-'P012'!$K5 -> 1821900 | M5: 40500
A6: Febrero | B6: 1821900 | C6: 1821900 | K6: ='P012'!$B6-('P012'!$C6+'P012'!$D6+'P012'!$E6+'P012'!$F6+'P012'!$G6+'P012'!$H6+'P012'!$I6+'P012'!$J6) -> 0 | L6: ='P012'!$B6-'P012'!$K6 -> 1821900 | M6: 40500
A7: Marzo | K7: ='P012'!$B7-('P012'!$C7+'P012'!$D7+'P012'!$E7+'P012'!$F7+'P012'!$G7+'P012'!$H7+'P012'!$I7+'P012'!$J7) -> 0 | L7: ='P012'!$B7-'P012'!$K7 -> 0
A8: Abril | K8: ='P012'!$B8-('P012'!$C8+'P012'!$D8+'P012'!$E8+'P012'!$F8+'P012'!$G8+'P012'!$H8+'P012'!$I8+'P012'!$J8) -> 0 | L8: ='P012'!$B8-'P012'!$K8 -> 0
A9: Mayo | K9: ='P012'!$B9-('P012'!$C9+'P012'!$D9+'P012'!$E9+'P012'!$F9+'P012'!$G9+'P012'!$H9+'P012'!$I9+'P012'!$J9) -> 0 | L9: ='P012'!$B9-'P012'!$K9 -> 0
A10: Junio | K10: ='P012'!$B10-('P012'!$C10+'P012'!$D10+'P012'!$E10+'P012'!$F10+'P012'!$G10+'P012'!$H10+'P012'!$I10+'P012'!$J10) -> 0 | L10: ='P012'!$B10-'P012'!$K10 -> 0
A11: Julio | K11: ='P012'!$B11-('P012'!$C11+'P012'!$D11+'P012'!$E11+'P012'!$F11+'P012'!$G11+'P012'!$H11+'P012'!$I11+'P012'!$J11) -> 0 | L11: ='P012'!$B11-'P012'!$K11 -> 0
A12: Agosto | K12: ='P012'!$B12-('P012'!$C12+'P012'!$D12+'P012'!$E12+'P012'!$F12+'P012'!$G12+'P012'!$H12+'P012'!$I12+'P012'!$J12) -> 0 | L12: ='P012'!$B12-'P012'!$K12 -> 0
A13: Septiembre | K13: ='P012'!$B13-('P012'!$C13+'P012'!$D13+'P012'!$E13+'P012'!$F13+'P012'!$G13+'P012'!$H13+'P012'!$I13+'P012'!$J13) -> 0 | L13: ='P012'!$B13-'P012'!$K13 -> 0
A14: Octubre | L14: ='P012'!$B14-'P012'!$K14 -> 0
A15: Noviembre | K15: ='P012'!$B15-('P012'!$C15+'P012'!$D15+'P012'!$E15+'P012'!$F15+'P012'!$G15+'P012'!$H15+'P012'!$I15+'P012'!$J15) -> 0 | L15: ='P012'!$B15-'P012'!$K15 -> 0
A16: Diciembre | K16: ='P012'!$B16-('P012'!$C16+'P012'!$D16+'P012'!$E16+'P012'!$F16+'P012'!$G16+'P012'!$H16+'P012'!$I16+'P012'!$J16) -> 0 | L16: ='P012'!$B16-'P012'!$K16 -> 0
A18: NRO DE RECIBOS DE LOS PAGOS
C19: RECIBO 1 | D19: RECIBO 2 | E19: RECIBO 3 | F19: RECIBO 4 | G19: RECIBO 5 | H19: RECIBO 6 | I19: RECIBO 7 | J19: RECIBO 8
A20: Enero | C20: 9625
A21: Febrero | C21: 9690
A22: Marzo
A23: Abril
A24: Mayo
A25: Junio
A26: Julio
A27: Agosto | K27: 9283
A28: Septiembre
A29: Octubre | K29: 9419
A30: Noviembre
A31: Diciembre

Sheet PO16
A1: 15/16/122/123 | C1: NORBERTO MAIDANA
A3: PAGOS DEL ALQUILER
B4: COSTO | C4: PAGO 1 | D4: PAGO 2 | E4: PAGO 3 | F4: PAGO 4 | G4: PAGO 5 | H4: PAGO 6 | I4: PAGO 7 | J4: PAGO 8 | K4: SALDO | L4: RECAUDADO | M4: interes | O4: impuesto | S4: DNI | T4: 24,572,126
A5: Enero | B5: 773200 | C5: 600 | K5: ='PO16'!$B5-('PO16'!$C5+'PO16'!$D5+'PO16'!$E5+'PO16'!$F5+'PO16'!$G5+'PO16'!$H5+'PO16'!$I5+'PO16'!$J5)+N5 -> 772600 | L5: ='PO16'!$B5-'PO16'!$K5 -> 600 | S5: DIRECCION | T5: 63a Cocomarola Oeste 9258 posadas
A6: Febrero | B6: 773200 | K6: ='PO16'!$B6-('PO16'!$C6+'PO16'!$D6+'PO16'!$E6+'PO16'!$F6+'PO16'!$G6+'PO16'!$H6+'PO16'!$I6+'PO16'!$J6)+N6 -> 773200 | L6: ='PO16'!$B6-'PO16'!$K6 -> 0 | S6: mail | T6: MPOLACO428-GMAIL.COM
A7: Marzo | B7: 773200 | K7: ='PO16'!$B7-('PO16'!$C7+'PO16'!$D7+'PO16'!$E7+'PO16'!$F7+'PO16'!$G7+'PO16'!$H7+'PO16'!$I7+'PO16'!$J7)+N7 -> 773200 | L7: ='PO16'!$B7-'PO16'!$K7 -> 0
A8: Abril | B8: 773200 | K8: ='PO16'!$B8-('PO16'!$C8+'PO16'!$D8+'PO16'!$E8+'PO16'!$F8+'PO16'!$G8+'PO16'!$H8+'PO16'!$I8+'PO16'!$J8)+N8 -> 773200 | L8: ='PO16'!$B8-'PO16'!$K8 -> 0
A9: Mayo | B9: 773200 | K9: ='PO16'!$B9-('PO16'!$C9+'PO16'!$D9+'PO16'!$E9+'PO16'!$F9+'PO16'!$G9+'PO16'!$H9+'PO16'!$I9+'PO16'!$J9)+N9 -> 773200 | L9: ='PO16'!$B9-'PO16'!$K9 -> 0
A10: Junio | K10: ='PO16'!$B10-('PO16'!$C10+'PO16'!$D10+'PO16'!$E10+'PO16'!$F10+'PO16'!$G10+'PO16'!$H10+'PO16'!$I10+'PO16'!$J10)+N10 -> 0 | L10: ='PO16'!$B10-'PO16'!$K10 -> 0
A11: Julio | K11: ='PO16'!$B11-('PO16'!$C11+'PO16'!$D11+'PO16'!$E11+'PO16'!$F11+'PO16'!$G11+'PO16'!$H11+'PO16'!$I11+'PO16'!$J11)+N11 -> 0 | L11: ='PO16'!$B11-'PO16'!$K11 -> 0
A12: Agosto | K12: ='PO16'!$B12-('PO16'!$C12+'PO16'!$D12+'PO16'!$E12+'PO16'!$F12+'PO16'!$G12+'PO16'!$H12+'PO16'!$I12+'PO16'!$J12)+N12 -> 0 | L12: ='PO16'!$B12-'PO16'!$K12 -> 0
A13: Septiembre | K13: ='PO16'!$B13-('PO16'!$C13+'PO16'!$D13+'PO16'!$E13+'PO16'!$F13+'PO16'!$G13+'PO16'!$H13+'PO16'!$I13+'PO16'!$J13)+N13 -> 0 | L13: ='PO16'!$B13-'PO16'!$K13 -> 0
A14: Octubre | K14: ='PO16'!$B14-('PO16'!$C14+'PO16'!$D14+'PO16'!$E14+'PO16'!$F14+'PO16'!$G14+'PO16'!$H14+'PO16'!$I14+'PO16'!$J14)+N14 -> 0 | L14: ='PO16'!$B14-'PO16'!$K14 -> 0
A15: Noviembre | K15: ='PO16'!$B15-('PO16'!$C15+'PO16'!$D15+'PO16'!$E15+'PO16'!$F15+'PO16'!$G15+'PO16'!$H15+'PO16'!$I15+'PO16'!$J15)+N15 -> 0 | L15: ='PO16'!$B15-'PO16'!$K15 -> 0
A16: Diciembre | K16: ='PO16'!$B16-('PO16'!$C16+'PO16'!$D16+'PO16'!$E16+'PO16'!$F16+'PO16'!$G16+'PO16'!$H16+'PO16'!$I16+'PO16'!$J16)+N16 -> 0 | L16: ='PO16'!$B16-'PO16'!$K16 -> 0
A18: NRO DE RECIBOS DE LOS PAGOS
C19: RECIBO 1 | D19: RECIBO 2 | E19: RECIBO 3 | F19: RECIBO 4 | G19: RECIBO 5 | H19: RECIBO 6 | I19: RECIBO 7 | J19: RECIBO 8
A20: Enero
A21: Febrero
A22: Marzo
A23: Abril
A24: Mayo
A25: Junio
A26: Julio
A27: Agosto
A28: Septiembre
A29: Octubre
A30: Noviembre
A31: Diciembre
N39: 12100
N40: 23350
N41: 13550
N42: 13550
N43: 3550
N44: 18500
N45: 16000
N46: 19500
N47: 14400
N48: 13400

Sheet Hoja 1

Sheet P014
A3: PAGOS DEL ALQUILER
B4: COSTO | C4: PAGO 1 | D4: PAGO 2 | E4: PAGO 3 | F4: PAGO 4 | G4: PAGO 5 | H4: PAGO 6 | I4: PAGO 7 | J4: PAGO 8 | K4: SALDO | L4: RECAUDADO
A5: Enero | K5: ='P014'!$B5-('P014'!$C5+'P014'!$D5+'P014'!$E5+'P014'!$F5+'P014'!$G5+'P014'!$H5+'P014'!$I5+'P014'!$J5) -> 0 | L5: ='P014'!$B5-'P014'!$K5 -> 0
A6: Febrero | K6: ='P014'!$B6-('P014'!$C6+'P014'!$D6+'P014'!$E6+'P014'!$F6+'P014'!$G6+'P014'!$H6+'P014'!$I6+'P014'!$J6) -> 0 | L6: ='P014'!$B6-'P014'!$K6 -> 0
A7: Marzo | K7: ='P014'!$B7-('P014'!$C7+'P014'!$D7+'P014'!$E7+'P014'!$F7+'P014'!$G7+'P014'!$H7+'P014'!$I7+'P014'!$J7) -> 0 | L7: ='P014'!$B7-'P014'!$K7 -> 0
A8: Abril | K8: ='P014'!$B8-('P014'!$C8+'P014'!$D8+'P014'!$E8+'P014'!$F8+'P014'!$G8+'P014'!$H8+'P014'!$I8+'P014'!$J8) -> 0 | L8: ='P014'!$B8-'P014'!$K8 -> 0
A9: Mayo | K9: ='P014'!$B9-('P014'!$C9+'P014'!$D9+'P014'!$E9+'P014'!$F9+'P014'!$G9+'P014'!$H9+'P014'!$I9+'P014'!$J9) -> 0 | L9: ='P014'!$B9-'P014'!$K9 -> 0
A10: Junio | K10: ='P014'!$B10-('P014'!$C10+'P014'!$D10+'P014'!$E10+'P014'!$F10+'P014'!$G10+'P014'!$H10+'P014'!$I10+'P014'!$J10) -> 0 | L10: ='P014'!$B10-'P014'!$K10 -> 0
A11: Julio | K11: ='P014'!$B11-('P014'!$C11+'P014'!$D11+'P014'!$E11+'P014'!$F11+'P014'!$G11+'P014'!$H11+'P014'!$I11+'P014'!$J11) -> 0 | L11: ='P014'!$B11-'P014'!$K11 -> 0
A12: Agosto | K12: ='P014'!$B12-('P014'!$C12+'P014'!$D12+'P014'!$E12+'P014'!$F12+'P014'!$G12+'P014'!$H12+'P014'!$I12+'P014'!$J12) -> 0 | L12: ='P014'!$B12-'P014'!$K12 -> 0
A13: Septiembre | K13: ='P014'!$B13-('P014'!$C13+'P014'!$D13+'P014'!$E13+'P014'!$F13+'P014'!$G13+'P014'!$H13+'P014'!$I13+'P014'!$J13) -> 0 | L13: ='P014'!$B13-'P014'!$K13 -> 0
A14: Octubre | K14: ='P014'!$B14-('P014'!$C14+'P014'!$D14+'P014'!$E14+'P014'!$F14+'P014'!$G14+'P014'!$H14+'P014'!$I14+'P014'!$J14) -> 0 | L14: ='P014'!$B14-'P014'!$K14 -> 0
A15: Noviembre | K15: ='P014'!$B15-('P014'!$C15+'P014'!$D15+'P014'!$E15+'P014'!$F15+'P014'!$G15+'P014'!$H15+'P014'!$I15+'P014'!$J15) -> 0 | L15: ='P014'!$B15-'P014'!$K15 -> 0
A16: Diciembre | K16: ='P014'!$B16-('P014'!$C16+'P014'!$D16+'P014'!$E16+'P014'!$F16+'P014'!$G16+'P014'!$H16+'P014'!$I16+'P014'!$J16) -> 0 | L16: ='P014'!$B16-'P014'!$K16 -> 0
A18: NRO DE RECIBOS DE LOS PAGOS
C19: RECIBO 1 | D19: RECIBO 2 | E19: RECIBO 3 | F19: RECIBO 4 | G19: RECIBO 5 | H19: RECIBO 6 | I19: RECIBO 7 | J19: RECIBO 8
A20: Enero
A21: Febrero
A22: Marzo
A23: Abril
A24: Mayo
A25: Junio
A26: Julio
A27: Agosto
A28: Septiembre
A29: Octubre
A30: Noviembre
A31: Diciembre

Sheet P015
A1: P015 | C1: PADILLA MARIA
A3: PAGOS DEL ALQUILER
B4: COSTO | C4: PAGO 1 | D4: PAGO 2 | E4: PAGO 3 | F4: PAGO 4 | G4: PAGO 5 | H4: PAGO 6 | I4: PAGO 7 | J4: PAGO 8 | K4: SALDO | L4: RECAUDADO
A5: Enero | B5: 22750 | C5: 22750 | K5: ='P015'!$B5-('P015'!$C5+'P015'!$D5+'P015'!$E5+'P015'!$F5+'P015'!$G5+'P015'!$H5+'P015'!$I5+'P015'!$J5) -> 0 | L5: ='P015'!$B5-'P015'!$K5 -> 22750
A6: Febrero | B6: 22750 | C6: 10000 | D6: 6000 | E6: 6750 | K6: ='P015'!$B6-('P015'!$C6+'P015'!$D6+'P015'!$E6+'P015'!$F6+'P015'!$G6+'P015'!$H6+'P015'!$I6+'P015'!$J6) -> 0 | L6: ='P015'!$B6-'P015'!$K6 -> 22750
A7: Marzo | K7: ='P015'!$B7-('P015'!$C7+'P015'!$D7+'P015'!$E7+'P015'!$F7+'P015'!$G7+'P015'!$H7+'P015'!$I7+'P015'!$J7) -> 0 | L7: ='P015'!$B7-'P015'!$K7 -> 0
A8: Abril | K8: ='P015'!$B8-('P015'!$C8+'P015'!$D8+'P015'!$E8+'P015'!$F8+'P015'!$G8+'P015'!$H8+'P015'!$I8+'P015'!$J8) -> 0 | L8: ='P015'!$B8-'P015'!$K8 -> 0
A9: Mayo | K9: ='P015'!$B9-('P015'!$C9+'P015'!$D9+'P015'!$E9+'P015'!$F9+'P015'!$G9+'P015'!$H9+'P015'!$I9+'P015'!$J9) -> 0 | L9: ='P015'!$B9-'P015'!$K9 -> 0
A10: Junio | K10: ='P015'!$B10-('P015'!$C10+'P015'!$D10+'P015'!$E10+'P015'!$F10+'P015'!$G10+'P015'!$H10+'P015'!$I10+'P015'!$J10) -> 0 | L10: ='P015'!$B10-'P015'!$K10 -> 0
A11: Julio | K11: ='P015'!$B11-('P015'!$C11+'P015'!$D11+'P015'!$E11+'P015'!$F11+'P015'!$G11+'P015'!$H11+'P015'!$I11+'P015'!$J11) -> 0 | L11: ='P015'!$B11-'P015'!$K11 -> 0
A12: Agosto | K12: ='P015'!$B12-('P015'!$C12+'P015'!$D12+'P015'!$E12+'P015'!$F12+'P015'!$G12+'P015'!$H12+'P015'!$I12+'P015'!$J12) -> 0 | L12: ='P015'!$B12-'P015'!$K12 -> 0
A13: Septiembre | K13: ='P015'!$B13-('P015'!$C13+'P015'!$D13+'P015'!$E13+'P015'!$F13+'P015'!$G13+'P015'!$H13+'P015'!$I13+'P015'!$J13) -> 0 | L13: ='P015'!$B13-'P015'!$K13 -> 0
A14: Octubre | K14: ='P015'!$B14-('P015'!$C14+'P015'!$D14+'P015'!$E14+'P015'!$F14+'P015'!$G14+'P015'!$H14+'P015'!$I14+'P015'!$J14) -> 0 | L14: ='P015'!$B14-'P015'!$K14 -> 0
A15: Noviembre | K15: ='P015'!$B15-('P015'!$C15+'P015'!$D15+'P015'!$E15+'P015'!$F15+'P015'!$G15+'P015'!$H15+'P015'!$I15+'P015'!$J15) -> 0 | L15: ='P015'!$B15-'P015'!$K15 -> 0
A16: Diciembre | K16: ='P015'!$B16-('P015'!$C16+'P015'!$D16+'P015'!$E16+'P015'!$F16+'P015'!$G16+'P015'!$H16+'P015'!$I16+'P015'!$J16) -> 0 | L16: ='P015'!$B16-'P015'!$K16 -> 0
A18: NRO DE RECIBOS DE LOS PAGOS
C19: RECIBO 1 | D19: RECIBO 2 | E19: RECIBO 3 | F19: RECIBO 4 | G19: RECIBO 5 | H19: RECIBO 6 | I19: RECIBO 7 | J19: RECIBO 8
A20: Enero | C20: 6537
A21: Febrero | C21: 6626 | D21: 6638 | E21: 6676
A22: Marzo
A23: Abril
A24: Mayo
A25: Junio
A26: Julio
A27: Agosto
A28: Septiembre
A29: Octubre
A30: Noviembre
A31: Diciembre

Sheet P017
A1: P17 | C1: GILDA FRANCO
A3: PAGOS DEL ALQUILER
B4: COSTO | C4: PAGO 1 | D4: PAGO 2 | E4: PAGO 3 | F4: PAGO 4 | G4: PAGO 5 | H4: PAGO 6 | I4: PAGO 7 | J4: PAGO 8 | K4: SALDO | L4: RECAUDADO
A5: Enero | B5: 177600 | K5: ='P017'!$B5-('P017'!$C5+'P017'!$D5+'P017'!$E5+'P017'!$F5+'P017'!$G5+'P017'!$H5+'P017'!$I5+'P017'!$J5) -> 177600 | L5: ='P017'!$B5-'P017'!$K5 -> 0
A6: Febrero | B6: 177600 | K6: ='P017'!$B6-('P017'!$C6+'P017'!$D6+'P017'!$E6+'P017'!$F6+'P017'!$G6+'P017'!$H6+'P017'!$I6+'P017'!$J6) -> 177600 | L6: ='P017'!$B6-'P017'!$K6 -> 0
A7: Marzo | B7: 193200 | K7: ='P017'!$B7-('P017'!$C7+'P017'!$D7+'P017'!$E7+'P017'!$F7+'P017'!$G7+'P017'!$H7+'P017'!$I7+'P017'!$J7) -> 193200 | L7: ='P017'!$B7-'P017'!$K7 -> 0
A8: Abril | B8: 193200 | K8: ='P017'!$B8-('P017'!$C8+'P017'!$D8+'P017'!$E8+'P017'!$F8+'P017'!$G8+'P017'!$H8+'P017'!$I8+'P017'!$J8) -> 193200 | L8: ='P017'!$B8-'P017'!$K8 -> 0
A9: Mayo | B9: 193200 | K9: ='P017'!$B9-('P017'!$C9+'P017'!$D9+'P017'!$E9+'P017'!$F9+'P017'!$G9+'P017'!$H9+'P017'!$I9+'P017'!$J9) -> 193200 | L9: ='P017'!$B9-'P017'!$K9 -> 0
A10: Junio | K10: ='P017'!$B10-('P017'!$C10+'P017'!$D10+'P017'!$E10+'P017'!$F10+'P017'!$G10+'P017'!$H10+'P017'!$I10+'P017'!$J10) -> 0 | L10: ='P017'!$B10-'P017'!$K10 -> 0
A11: Julio | K11: ='P017'!$B11-('P017'!$C11+'P017'!$D11+'P017'!$E11+'P017'!$F11+'P017'!$G11+'P017'!$H11+'P017'!$I11+'P017'!$J11) -> 0 | L11: ='P017'!$B11-'P017'!$K11 -> 0
A12: Agosto | K12: ='P017'!$B12-('P017'!$C12+'P017'!$D12+'P017'!$E12+'P017'!$F12+'P017'!$G12+'P017'!$H12+'P017'!$I12+'P017'!$J12) -> 0 | L12: ='P017'!$B12-'P017'!$K12 -> 0
A13: Septiembre | K13: ='P017'!$B13-('P017'!$C13+'P017'!$D13+'P017'!$E13+'P017'!$F13+'P017'!$G13+'P017'!$H13+'P017'!$I13+'P017'!$J13) -> 0 | L13: ='P017'!$B13-'P017'!$K13 -> 0
A14: Octubre | K14: ='P017'!$B14-('P017'!$C14+'P017'!$D14+'P017'!$E14+'P017'!$F14+'P017'!$G14+'P017'!$H14+'P017'!$I14+'P017'!$J14) -> 0 | L14: ='P017'!$B14-'P017'!$K14 -> 0
A15: Noviembre | K15: ='P017'!$B15-('P017'!$C15+'P017'!$D15+'P017'!$E15+'P017'!$F15+'P017'!$G15+'P017'!$H15+'P017'!$I15+'P017'!$J15) -> 0 | L15: ='P017'!$B15-'P017'!$K15 -> 0
A16: Diciembre | K16: ='P017'!$B16-('P017'!$C16+'P017'!$D16+'P017'!$E16+'P017'!$F16+'P017'!$G16+'P017'!$H16+'P017'!$I16+'P017'!$J16) -> 0 | L16: ='P017'!$B16-'P017'!$K16 -> 0
A18: NRO DE RECIBOS DE LOS PAGOS
C19: RECIBO 1 | D19: RECIBO 2 | E19: RECIBO 3 | F19: RECIBO 4 | G19: RECIBO 5 | H19: RECIBO 6 | I19: RECIBO 7 | J19: RECIBO 8
A20: Enero
A21: Febrero
A22: Marzo
A23: Abril
A24: Mayo
A25: Junio
A26: Julio
A27: Agosto
A28: Septiembre
A29: Octubre
A30: Noviembre
A31: Diciembre

Sheet P018
A3: PAGOS DEL ALQUILER
B4: COSTO | C4: PAGO 1 | D4: PAGO 2 | E4: PAGO 3 | F4: PAGO 4 | G4: PAGO 5 | H4: PAGO 6 | I4: PAGO 7 | J4: PAGO 8 | K4: SALDO | L4: RECAUDADO
A5: Enero | K5: ='P018'!$B5-('P018'!$C5+'P018'!$D5+'P018'!$E5+'P018'!$F5+'P018'!$G5+'P018'!$H5+'P018'!$I5+'P018'!$J5) -> 0 | L5: ='P018'!$B5-'P018'!$K5 -> 0
A6: Febrero | K6: ='P018'!$B6-('P018'!$C6+'P018'!$D6+'P018'!$E6+'P018'!$F6+'P018'!$G6+'P018'!$H6+'P018'!$I6+'P018'!$J6) -> 0 | L6: ='P018'!$B6-'P018'!$K6 -> 0
A7: Marzo | K7: ='P018'!$B7-('P018'!$C7+'P018'!$D7+'P018'!$E7+'P018'!$F7+'P018'!$G7+'P018'!$H7+'P018'!$I7+'P018'!$J7) -> 0 | L7: ='P018'!$B7-'P018'!$K7 -> 0
A8: Abril | K8: ='P018'!$B8-('P018'!$C8+'P018'!$D8+'P018'!$E8+'P018'!$F8+'P018'!$G8+'P018'!$H8+'P018'!$I8+'P018'!$J8) -> 0 | L8: ='P018'!$B8-'P018'!$K8 -> 0
A9: Mayo | K9: ='P018'!$B9-('P018'!$C9+'P018'!$D9+'P018'!$E9+'P018'!$F9+'P018'!$G9+'P018'!$H9+'P018'!$I9+'P018'!$J9) -> 0 | L9: ='P018'!$B9-'P018'!$K9 -> 0
A10: Junio | K10: ='P018'!$B10-('P018'!$C10+'P018'!$D10+'P018'!$E10+'P018'!$F10+'P018'!$G10+'P018'!$H10+'P018'!$I10+'P018'!$J10) -> 0 | L10: ='P018'!$B10-'P018'!$K10 -> 0
A11: Julio | K11: ='P018'!$B11-('P018'!$C11+'P018'!$D11+'P018'!$E11+'P018'!$F11+'P018'!$G11+'P018'!$H11+'P018'!$I11+'P018'!$J11) -> 0 | L11: ='P018'!$B11-'P018'!$K11 -> 0
A12: Agosto | K12: ='P018'!$B12-('P018'!$C12+'P018'!$D12+'P018'!$E12+'P018'!$F12+'P018'!$G12+'P018'!$H12+'P018'!$I12+'P018'!$J12) -> 0 | L12: ='P018'!$B12-'P018'!$K12 -> 0
A13: Septiembre | K13: ='P018'!$B13-('P018'!$C13+'P018'!$D13+'P018'!$E13+'P018'!$F13+'P018'!$G13+'P018'!$H13+'P018'!$I13+'P018'!$J13) -> 0 | L13: ='P018'!$B13-'P018'!$K13 -> 0
A14: Octubre | K14: ='P018'!$B14-('P018'!$C14+'P018'!$D14+'P018'!$E14+'P018'!$F14+'P018'!$G14+'P018'!$H14+'P018'!$I14+'P018'!$J14) -> 0 | L14: ='P018'!$B14-'P018'!$K14 -> 0
A15: Noviembre | K15: ='P018'!$B15-('P018'!$C15+'P018'!$D15+'P018'!$E15+'P018'!$F15+'P018'!$G15+'P018'!$H15+'P018'!$I15+'P018'!$J15) -> 0 | L15: ='P018'!$B15-'P018'!$K15 -> 0
A16: Diciembre | K16: ='P018'!$B16-('P018'!$C16+'P018'!$D16+'P018'!$E16+'P018'!$F16+'P018'!$G16+'P018'!$H16+'P018'!$I16+'P018'!$J16) -> 0 | L16: ='P018'!$B16-'P018'!$K16 -> 0
A18: NRO DE RECIBOS DE LOS PAGOS
C19: RECIBO 1 | D19: RECIBO 2 | E19: RECIBO 3 | F19: RECIBO 4 | G19: RECIBO 5 | H19: RECIBO 6 | I19: RECIBO 7 | J19: RECIBO 8
A20: Enero
A21: Febrero
A22: Marzo
A23: Abril
A24: Mayo
A25: Junio
A26: Julio
A27: Agosto
A28: Septiembre
A29: Octubre
A30: Noviembre
A31: Diciembre

Sheet P019
A3: PAGOS DEL ALQUILER
B4: COSTO | C4: PAGO 1 | D4: PAGO 2 | E4: PAGO 3 | F4: PAGO 4 | G4: PAGO 5 | H4: PAGO 6 | I4: PAGO 7 | J4: PAGO 8 | K4: SALDO | L4: RECAUDADO
A5: Enero | K5: ='P019'!$B5-('P019'!$C5+'P019'!$D5+'P019'!$E5+'P019'!$F5+'P019'!$G5+'P019'!$H5+'P019'!$I5+'P019'!$J5) -> 0 | L5: ='P019'!$B5-'P019'!$K5 -> 0
A6: Febrero | K6: ='P019'!$B6-('P019'!$C6+'P019'!$D6+'P019'!$E6+'P019'!$F6+'P019'!$G6+'P019'!$H6+'P019'!$I6+'P019'!$J6) -> 0 | L6: ='P019'!$B6-'P019'!$K6 -> 0
A7: Marzo | K7: ='P019'!$B7-('P019'!$C7+'P019'!$D7+'P019'!$E7+'P019'!$F7+'P019'!$G7+'P019'!$H7+'P019'!$I7+'P019'!$J7) -> 0 | L7: ='P019'!$B7-'P019'!$K7 -> 0
A8: Abril | K8: ='P019'!$B8-('P019'!$C8+'P019'!$D8+'P019'!$E8+'P019'!$F8+'P019'!$G8+'P019'!$H8+'P019'!$I8+'P019'!$J8) -> 0 | L8: ='P019'!$B8-'P019'!$K8 -> 0
A9: Mayo | K9: ='P019'!$B9-('P019'!$C9+'P019'!$D9+'P019'!$E9+'P019'!$F9+'P019'!$G9+'P019'!$H9+'P019'!$I9+'P019'!$J9) -> 0 | L9: ='P019'!$B9-'P019'!$K9 -> 0
A10: Junio | K10: ='P019'!$B10-('P019'!$C10+'P019'!$D10+'P019'!$E10+'P019'!$F10+'P019'!$G10+'P019'!$H10+'P019'!$I10+'P019'!$J10) -> 0 | L10: ='P019'!$B10-'P019'!$K10 -> 0
A11: Julio | K11: ='P019'!$B11-('P019'!$C11+'P019'!$D11+'P019'!$E11+'P019'!$F11+'P019'!$G11+'P019'!$H11+'P019'!$I11+'P019'!$J11) -> 0 | L11: ='P019'!$B11-'P019'!$K11 -> 0
A12: Agosto | K12: ='P019'!$B12-('P019'!$C12+'P019'!$D12+'P019'!$E12+'P019'!$F12+'P019'!$G12+'P019'!$H12+'P019'!$I12+'P019'!$J12) -> 0 | L12: ='P019'!$B12-'P019'!$K12 -> 0
A13: Septiembre | K13: ='P019'!$B13-('P019'!$C13+'P019'!$D13+'P019'!$E13+'P019'!$F13+'P019'!$G13+'P019'!$H13+'P019'!$I13+'P019'!$J13) -> 0 | L13: ='P019'!$B13-'P019'!$K13 -> 0
A14: Octubre | K14: ='P019'!$B14-('P019'!$C14+'P019'!$D14+'P019'!$E14+'P019'!$F14+'P019'!$G14+'P019'!$H14+'P019'!$I14+'P019'!$J14) -> 0 | L14: ='P019'!$B14-'P019'!$K14 -> 0
A15: Noviembre | K15: ='P019'!$B15-('P019'!$C15+'P019'!$D15+'P019'!$E15+'P019'!$F15+'P019'!$G15+'P019'!$H15+'P019'!$I15+'P019'!$J15) -> 0 | L15: ='P019'!$B15-'P019'!$K15 -> 0
A16: Diciembre | K16: ='P019'!$B16-('P019'!$C16+'P019'!$D16+'P019'!$E16+'P019'!$F16+'P019'!$G16+'P019'!$H16+'P019'!$I16+'P019'!$J16) -> 0 | L16: ='P019'!$B16-'P019'!$K16 -> 0
A18: NRO DE RECIBOS DE LOS PAGOS
C19: RECIBO 1 | D19: RECIBO 2 | E19: RECIBO 3 | F19: RECIBO 4 | G19: RECIBO 5 | H19: RECIBO 6 | I19: RECIBO 7 | J19: RECIBO 8
A20: Enero
A21: Febrero
A22: Marzo
A23: Abril
A24: Mayo
A25: Junio
A26: Julio
A27: Agosto
A28: Septiembre
A29: Octubre
A30: Noviembre
A31: Diciembre

Sheet P020
A3: PAGOS DEL ALQUILER
B4: COSTO | C4: PAGO 1 | D4: PAGO 2 | E4: PAGO 3 | F4: PAGO 4 | G4: PAGO 5 | H4: PAGO 6 | I4: PAGO 7 | J4: PAGO 8 | K4: SALDO | L4: RECAUDADO
A5: Enero | K5: ='P020'!$B5-('P020'!$C5+'P020'!$D5+'P020'!$E5+'P020'!$F5+'P020'!$G5+'P020'!$H5+'P020'!$I5+'P020'!$J5) -> 0 | L5: ='P020'!$B5-'P020'!$K5 -> 0
A6: Febrero | K6: ='P020'!$B6-('P020'!$C6+'P020'!$D6+'P020'!$E6+'P020'!$F6+'P020'!$G6+'P020'!$H6+'P020'!$I6+'P020'!$J6) -> 0 | L6: ='P020'!$B6-'P020'!$K6 -> 0
A7: Marzo | K7: ='P020'!$B7-('P020'!$C7+'P020'!$D7+'P020'!$E7+'P020'!$F7+'P020'!$G7+'P020'!$H7+'P020'!$I7+'P020'!$J7) -> 0 | L7: ='P020'!$B7-'P020'!$K7 -> 0
A8: Abril | K8: ='P020'!$B8-('P020'!$C8+'P020'!$D8+'P020'!$E8+'P020'!$F8+'P020'!$G8+'P020'!$H8+'P020'!$I8+'P020'!$J8) -> 0 | L8: ='P020'!$B8-'P020'!$K8 -> 0
A9: Mayo | K9: ='P020'!$B9-('P020'!$C9+'P020'!$D9+'P020'!$E9+'P020'!$F9+'P020'!$G9+'P020'!$H9+'P020'!$I9+'P020'!$J9) -> 0 | L9: ='P020'!$B9-'P020'!$K9 -> 0
A10: Junio | K10: ='P020'!$B10-('P020'!$C10+'P020'!$D10+'P020'!$E10+'P020'!$F10+'P020'!$G10+'P020'!$H10+'P020'!$I10+'P020'!$J10) -> 0 | L10: ='P020'!$B10-'P020'!$K10 -> 0
A11: Julio | K11: ='P020'!$B11-('P020'!$C11+'P020'!$D11+'P020'!$E11+'P020'!$F11+'P020'!$G11+'P020'!$H11+'P020'!$I11+'P020'!$J11) -> 0 | L11: ='P020'!$B11-'P020'!$K11 -> 0
A12: Agosto | K12: ='P020'!$B12-('P020'!$C12+'P020'!$D12+'P020'!$E12+'P020'!$F12+'P020'!$G12+'P020'!$H12+'P020'!$I12+'P020'!$J12) -> 0 | L12: ='P020'!$B12-'P020'!$K12 -> 0
A13: Septiembre | K13: ='P020'!$B13-('P020'!$C13+'P020'!$D13+'P020'!$E13+'P020'!$F13+'P020'!$G13+'P020'!$H13+'P020'!$I13+'P020'!$J13) -> 0 | L13: ='P020'!$B13-'P020'!$K13 -> 0
A14: Octubre | K14: ='P020'!$B14-('P020'!$C14+'P020'!$D14+'P020'!$E14+'P020'!$F14+'P020'!$G14+'P020'!$H14+'P020'!$I14+'P020'!$J14) -> 0 | L14: ='P020'!$B14-'P020'!$K14 -> 0
A15: Noviembre | K15: ='P020'!$B15-('P020'!$C15+'P020'!$D15+'P020'!$E15+'P020'!$F15+'P020'!$G15+'P020'!$H15+'P020'!$I15+'P020'!$J15) -> 0 | L15: ='P020'!$B15-'P020'!$K15 -> 0
A16: Diciembre | K16: ='P020'!$B16-('P020'!$C16+'P020'!$D16+'P020'!$E16+'P020'!$F16+'P020'!$G16+'P020'!$H16+'P020'!$I16+'P020'!$J16) -> 0 | L16: ='P020'!$B16-'P020'!$K16 -> 0
A18: NRO DE RECIBOS DE LOS PAGOS
C19: RECIBO 1 | D19: RECIBO 2 | E19: RECIBO 3 | F19: RECIBO 4 | G19: RECIBO 5 | H19: RECIBO 6 | I19: RECIBO 7 | J19: RECIBO 8
A20: Enero
A21: Febrero
A22: Marzo
A23: Abril
A24: Mayo
A25: Junio
A26: Julio
A27: Agosto
A28: Septiembre
A29: Octubre
A30: Noviembre
A31: Diciembre

Sheet P022
A3: PAGOS DEL ALQUILER
B4: COSTO | C4: PAGO 1 | D4: PAGO 2 | E4: PAGO 3 | F4: PAGO 4 | G4: PAGO 5 | H4: PAGO 6 | I4: PAGO 7 | J4: PAGO 8 | K4: SALDO | L4: RECAUDADO
A5: Enero | K5: ='P022'!$B5-('P022'!$C5+'P022'!$D5+'P022'!$E5+'P022'!$F5+'P022'!$G5+'P022'!$H5+'P022'!$I5+'P022'!$J5) -> 0 | L5: ='P022'!$B5-'P022'!$K5 -> 0
A6: Febrero | K6: ='P022'!$B6-('P022'!$C6+'P022'!$D6+'P022'!$E6+'P022'!$F6+'P022'!$G6+'P022'!$H6+'P022'!$I6+'P022'!$J6) -> 0 | L6: ='P022'!$B6-'P022'!$K6 -> 0
A7: Marzo | K7: ='P022'!$B7-('P022'!$C7+'P022'!$D7+'P022'!$E7+'P022'!$F7+'P022'!$G7+'P022'!$H7+'P022'!$I7+'P022'!$J7) -> 0 | L7: ='P022'!$B7-'P022'!$K7 -> 0
A8: Abril | K8: ='P022'!$B8-('P022'!$C8+'P022'!$D8+'P022'!$E8+'P022'!$F8+'P022'!$G8+'P022'!$H8+'P022'!$I8+'P022'!$J8) -> 0 | L8: ='P022'!$B8-'P022'!$K8 -> 0
A9: Mayo | K9: ='P022'!$B9-('P022'!$C9+'P022'!$D9+'P022'!$E9+'P022'!$F9+'P022'!$G9+'P022'!$H9+'P022'!$I9+'P022'!$J9) -> 0 | L9: ='P022'!$B9-'P022'!$K9 -> 0
A10: Junio | K10: ='P022'!$B10-('P022'!$C10+'P022'!$D10+'P022'!$E10+'P022'!$F10+'P022'!$G10+'P022'!$H10+'P022'!$I10+'P022'!$J10) -> 0 | L10: ='P022'!$B10-'P022'!$K10 -> 0
A11: Julio | K11: ='P022'!$B11-('P022'!$C11+'P022'!$D11+'P022'!$E11+'P022'!$F11+'P022'!$G11+'P022'!$H11+'P022'!$I11+'P022'!$J11) -> 0 | L11: ='P022'!$B11-'P022'!$K11 -> 0
A12: Agosto | K12: ='P022'!$B12-('P022'!$C12+'P022'!$D12+'P022'!$E12+'P022'!$F12+'P022'!$G12+'P022'!$H12+'P022'!$I12+'P022'!$J12) -> 0 | L12: ='P022'!$B12-'P022'!$K12 -> 0
A13: Septiembre | K13: ='P022'!$B13-('P022'!$C13+'P022'!$D13+'P022'!$E13+'P022'!$F13+'P022'!$G13+'P022'!$H13+'P022'!$I13+'P022'!$J13) -> 0 | L13: ='P022'!$B13-'P022'!$K13 -> 0
A14: Octubre | K14: ='P022'!$B14-('P022'!$C14+'P022'!$D14+'P022'!$E14+'P022'!$F14+'P022'!$G14+'P022'!$H14+'P022'!$I14+'P022'!$J14) -> 0 | L14: ='P022'!$B14-'P022'!$K14 -> 0
A15: Noviembre | K15: ='P022'!$B15-('P022'!$C15+'P022'!$D15+'P022'!$E15+'P022'!$F15+'P022'!$G15+'P022'!$H15+'P022'!$I15+'P022'!$J15) -> 0 | L15: ='P022'!$B15-'P022'!$K15 -> 0
A16: Diciembre | K16: ='P022'!$B16-('P022'!$C16+'P022'!$D16+'P022'!$E16+'P022'!$F16+'P022'!$G16+'P022'!$H16+'P022'!$I16+'P022'!$J16) -> 0 | L16: ='P022'!$B16-'P022'!$K16 -> 0
A18: NRO DE RECIBOS DE LOS PAGOS
C19: RECIBO 1 | D19: RECIBO 2 | E19: RECIBO 3 | F19: RECIBO 4 | G19: RECIBO 5 | H19: RECIBO 6 | I19: RECIBO 7 | J19: RECIBO 8
A20: Enero
A21: Febrero
A22: Marzo
A23: Abril
A24: Mayo
A25: Junio
A26: Julio
A27: Agosto
A28: Septiembre
A29: Octubre
A30: Noviembre
A31: Diciembre

Sheet P023
A1: P023 | C1: NIELSEN HERNAN
A3: PAGOS DEL ALQUILER
B4: COSTO | C4: PAGO 1 | D4: PAGO 2 | E4: PAGO 3 | F4: PAGO 4 | G4: PAGO 5 | H4: PAGO 6 | I4: PAGO 7 | J4: PAGO 8 | K4: SALDO | L4: RECAUDADO
A5: Enero | B5: 110500 | C5: 110500 | K5: ='P023'!$B5-('P023'!$C5+'P023'!$D5+'P023'!$E5+'P023'!$F5+'P023'!$G5+'P023'!$H5+'P023'!$I5+'P023'!$J5) -> 0 | L5: ='P023'!$B5-'P023'!$K5 -> 110500
A6: Febrero | B6: 110500 | C6: 60000 | D6: 50500 | K6: ='P023'!$B6-('P023'!$C6+'P023'!$D6+'P023'!$E6+'P023'!$F6+'P023'!$G6+'P023'!$H6+'P023'!$I6+'P023'!$J6) -> 0 | L6: ='P023'!$B6-'P023'!$K6 -> 110500
A7: Marzo | B7: 110500 | C7: 80000 | D7: 30500 | K7: ='P023'!$B7-('P023'!$C7+'P023'!$D7+'P023'!$E7+'P023'!$F7+'P023'!$G7+'P023'!$H7+'P023'!$I7+'P023'!$J7) -> 0 | L7: ='P023'!$B7-'P023'!$K7 -> 110500
A8: Abril | B8: 110500 | C8: 78400 | D8: 32100 | K8: ='P023'!$B8-('P023'!$C8+'P023'!$D8+'P023'!$E8+'P023'!$F8+'P023'!$G8+'P023'!$H8+'P023'!$I8+'P023'!$J8) -> 0 | L8: ='P023'!$B8-'P023'!$K8 -> 110500
A9: Mayo | K9: ='P023'!$B9-('P023'!$C9+'P023'!$D9+'P023'!$E9+'P023'!$F9+'P023'!$G9+'P023'!$H9+'P023'!$I9+'P023'!$J9) -> 0 | L9: ='P023'!$B9-'P023'!$K9 -> 0
A10: Junio | K10: ='P023'!$B10-('P023'!$C10+'P023'!$D10+'P023'!$E10+'P023'!$F10+'P023'!$G10+'P023'!$H10+'P023'!$I10+'P023'!$J10) -> 0 | L10: ='P023'!$B10-'P023'!$K10 -> 0
A11: Julio | K11: ='P023'!$B11-('P023'!$C11+'P023'!$D11+'P023'!$E11+'P023'!$F11+'P023'!$G11+'P023'!$H11+'P023'!$I11+'P023'!$J11) -> 0 | L11: ='P023'!$B11-'P023'!$K11 -> 0
A12: Agosto | K12: ='P023'!$B12-('P023'!$C12+'P023'!$D12+'P023'!$E12+'P023'!$F12+'P023'!$G12+'P023'!$H12+'P023'!$I12+'P023'!$J12) -> 0 | L12: ='P023'!$B12-'P023'!$K12 -> 0
A13: Septiembre | K13: ='P023'!$B13-('P023'!$C13+'P023'!$D13+'P023'!$E13+'P023'!$F13+'P023'!$G13+'P023'!$H13+'P023'!$I13+'P023'!$J13) -> 0 | L13: ='P023'!$B13-'P023'!$K13 -> 0
A14: Octubre | K14: ='P023'!$B14-('P023'!$C14+'P023'!$D14+'P023'!$E14+'P023'!$F14+'P023'!$G14+'P023'!$H14+'P023'!$I14+'P023'!$J14) -> 0 | L14: ='P023'!$B14-'P023'!$K14 -> 0
A15: Noviembre | K15: ='P023'!$B15-('P023'!$C15+'P023'!$D15+'P023'!$E15+'P023'!$F15+'P023'!$G15+'P023'!$H15+'P023'!$I15+'P023'!$J15) -> 0 | L15: ='P023'!$B15-'P023'!$K15 -> 0
A16: Diciembre | K16: ='P023'!$B16-('P023'!$C16+'P023'!$D16+'P023'!$E16+'P023'!$F16+'P023'!$G16+'P023'!$H16+'P023'!$I16+'P023'!$J16) -> 0 | L16: ='P023'!$B16-'P023'!$K16 -> 0
A18: NRO DE RECIBOS DE LOS PAGOS
C19: RECIBO 1 | D19: RECIBO 2 | E19: RECIBO 3 | F19: RECIBO 4 | G19: RECIBO 5 | H19: RECIBO 6 | I19: RECIBO 7 | J19: RECIBO 8
A20: Enero | C20: 6588
A21: Febrero | C21: 6668 | D21: 6695
A22: Marzo | C22: 6771 | D22: 6792
A23: Abril | C23: 6848 | D23: 6869
A24: Mayo
A25: Junio
A26: Julio
A27: Agosto
A28: Septiembre
A29: Octubre
A30: Noviembre
A31: Diciembre

Sheet P021
A1: 645850 | C1: OSMAR GONZANLEZ
A3: PAGOS DEL ALQUILER
B4: COSTO | C4: PAGO 1 | D4: PAGO 2 | E4: PAGO 3 | F4: PAGO 4 | G4: PAGO 5 | H4: PAGO 6 | I4: PAGO 7 | J4: PAGO 8 | K4: SALDO | L4: RECAUDADO
A5: Enero | B5: 710435 | C5: 710435 | K5: ='P021'!$B5-('P021'!$C5+'P021'!$D5+'P021'!$E5+'P021'!$F5+'P021'!$G5+'P021'!$H5+'P021'!$I5+'P021'!$J5) -> 0 | L5: 710435 | M5: 13500
A6: Febrero | B6: 710435 | C6: 710435 | K6: ='P021'!$B6-('P021'!$C6+'P021'!$D6+'P021'!$E6+'P021'!$F6+'P021'!$G6+'P021'!$H6+'P021'!$I6+'P021'!$J6) -> 0 | L6: ='P021'!$B6-'P021'!$K6 -> 710435 | M6: 13500
A7: Marzo | B7: 772950 | K7: ='P021'!$B7-('P021'!$C7+'P021'!$D7+'P021'!$E7+'P021'!$F7+'P021'!$G7+'P021'!$H7+'P021'!$I7+'P021'!$J7) -> 772950 | L7: ='P021'!$B7-'P021'!$K7 -> 0
A8: Abril | B8: 772950 | K8: ='P021'!$B8-('P021'!$C8+'P021'!$D8+'P021'!$E8+'P021'!$F8+'P021'!$G8+'P021'!$H8+'P021'!$I8+'P021'!$J8) -> 772950 | L8: ='P021'!$B8-'P021'!$K8 -> 0
A9: Mayo | B9: 772950 | K9: ='P021'!$B9-('P021'!$C9+'P021'!$D9+'P021'!$E9+'P021'!$F9+'P021'!$G9+'P021'!$H9+'P021'!$I9+'P021'!$J9) -> 772950 | L9: ='P021'!$B9-'P021'!$K9 -> 0
A10: Junio | K10: ='P021'!$B10-('P021'!$C10+'P021'!$D10+'P021'!$E10+'P021'!$F10+'P021'!$G10+'P021'!$H10+'P021'!$I10+'P021'!$J10) -> 0 | L10: ='P021'!$B10-'P021'!$K10 -> 0
A11: Julio | K11: ='P021'!$B11-('P021'!$C11+'P021'!$D11+'P021'!$E11+'P021'!$F11+'P021'!$G11+'P021'!$H11+'P021'!$I11+'P021'!$J11) -> 0 | L11: ='P021'!$B11-'P021'!$K11 -> 0
A12: Agosto | K12: ='P021'!$B12-('P021'!$C12+'P021'!$D12+'P021'!$E12+'P021'!$F12+'P021'!$G12+'P021'!$H12+'P021'!$I12+'P021'!$J12) -> 0 | L12: ='P021'!$B12-'P021'!$K12 -> 0
A13: Septiembre | K13: ='P021'!$B13-('P021'!$C13+'P021'!$D13+'P021'!$E13+'P021'!$F13+'P021'!$G13+'P021'!$H13+'P021'!$I13+'P021'!$J13) -> 0 | L13: ='P021'!$B13-'P021'!$K13 -> 0
A14: Octubre | K14: ='P021'!$B14-('P021'!$C14+'P021'!$D14+'P021'!$E14+'P021'!$F14+'P021'!$G14+'P021'!$H14+'P021'!$I14+'P021'!$J14) -> 0 | L14: ='P021'!$B14-'P021'!$K14 -> 0
A15: Noviembre | K15: ='P021'!$B15-('P021'!$C15+'P021'!$D15+'P021'!$E15+'P021'!$F15+'P021'!$G15+'P021'!$H15+'P021'!$I15+'P021'!$J15) -> 0 | L15: ='P021'!$B15-'P021'!$K15 -> 0
